Workbook

Sheet 医院
A1: 数据名 | B1: 计量单位 | C1: 填报部门 | D1: Y2021 | E1: Y2020 | F1: Y2019 | G1: 指标说明 | H1: 计算公式
A2: 下转患者人次数 | B2: 人次 | C2: 医务科 | D2: 10291 | E2: 10118 | F2: 9839 | G2: 参考三级中医、三级公立国考手册,原指标名为:下转患者人次数（门急诊、住院） | H2: 门急诊下转患者人次数+住院下转患者人次数。
A3: 出院患者手术占比 | B3: % | C3: 统计室 | D3: 30.063321 | E3: 28.092117 | F3: 28.147768 | G3: 详见三级公立、二级公立国考手册。举例：30%请填写30（不带百分号），而非写成30%，或0.3。下同 | H3: 出院患者手术台次数/同期出院患者总人次数*100
A4: 出院患者微创手术占比 | B4: % | C4: 统计室 | D4: 20.651888 | E4: 19.676328 | F4: 17.502871 | G4: 详见三级公立、二级公立国考手册 | H4: 出院患者微创手术台次数/同期出院患者手术台次数*100
A5: 出院患者四级手术比例 | B5: % | C5: 统计室 | D5: 21.873519 | E5: 18.784758 | F5: 17.427235 | G5: 详见三级公立国考手册 | H5: 出院患者四级手术台次数/同期出院患者手术台次数*100
A6: 出院患者疑难危重病例比例 | B6: % | C6: 统计室 | D6: 94.43 | E6: 91.95 | F6: 89.52 | G6: 即CD型病例占比 | H6: (疑难病例数+危重病例数)/出院人数*100
A7: 特需医疗服务量占比 | B7: % | C7: 医务科 | D7: 1.2 | E7: 0.8 | F7: 0.25 | G7: 参考三级公立国考手册，特需医疗服务占比的构成要素。 | H7: 特需医疗服务量/同期全部医疗服务量*100
A8: 特需医疗服务收入占比 | B8: % | C8: 医务科 | D8: 0.11 | E8: 0.0351 | F8: 0.0424 | G8: 参考三级公立国考手册，特需医疗服务占比的构成要素 | H8: 特需医疗服务收入/同期全部医疗服务收入*100
A9: 手术患者并发症发生率 | B9: % | C9: 质控科 | D9: 0.0036493713 | E9: 0.0054100228 | F9: 0.0052552841 | G9: 详见国考手册 | H9: 手术患者并发症发生例数/同期出院的手术患者人数*100
A10: I类切口手术部位感染率 | B10: % | C10: 院感科 | D10: 0.05 | E10: 0.05 | F10: 0.09 | G10: 详见三级中医、三级公立国考手册 | H10: I类切口手术部位感染人次数/同期I类切口手术台次数*100
A11: 大型医用设备检查阳性率 | B11: % | C11: 医务科 | D11: 94.22 | E11: 93.10 | F11: 85.13 | G11: 详见三级中医、三级公立国考手册 | H11: 大型医用设备检查阳性数/同期大型医用设备检查人次数*100
A12: 国家室间质量评价临床检验项目参加率 | B12: % | C12: 医务科 | D12: 92.65 | E12: 96.28 | F12: 81.25 | G12: 参考三级中医、三级公立国考手册，为“通过国家室间质量评价的临床检验项目数”指标的构成要素 | H12: 参加国家临床检验中心组织的室间质评的检验项目数/同期实验室已开展且同时国家临床检验中心已组织的室间质评检验项目总数*100
A13: 国家室间质量评价临床检验项目合格率 | B13: % | C13: 医务科 | D13: 99.11 | E13: 97.10 | F13: 96.79 | G13: 参考三级中医、三级公立国考手册，为“通过国家室间质量评价的临床检验项目数”指标的构成要素 | H13: 参加国家临床检验中心组织室间质评成绩合格的检验项目数/同期参加国家临床检验中心组织的室间质评检验项目总数*100
A14: 低风险组病例死亡率 | B14: % | C14: 质控科 | D14: 0 | E14: 0 | F14: 0 | G14: 详见三级公立、二级公立国考手册 | H14: 低风险组死亡例数/低风险组病例数*100
A15: 优质护理服务病房覆盖率 | B15: % | C15: 护理部 | D15: 100 | E15: 100 | F15: 100 | G15: 参考三级中医、三级公立国考手册，病房总数（即病区数） | H15: 全院已经开展优质护理服务的病房总数/全院病房总数*100
A16: 医院感染发生率 | B16: % | C16: 院感科 | D16: 0.91 | E16: 1 | F16: 1.19 | G16: 等级评审标准细则
A17: 点评处方占处方总数的比例 | B17: % | C17: 药学部 | D17: 3.09 | E17: 3.03 | F17: 0.43 | G17: 详见三级中医、三级公立国考手册 | H17: 点评处方数/处方总数*100
A18: 抗菌药物使用强度DDDs | B18: DDD | C18: 药学部 | D18: 37.96 | E18: 38.91 | F18: 39.57 | G18: 详见国考手册 | H18: 住院患者抗菌药物消耗量（累计DDD数）/同期收治患者人天数*100
A19: 门诊患者基本药物处方占比 | B19: % | C19: 药学部 | D19: 70.49 | E19: 61.55 | F19: 58.71 | G19: 详见三级中医、三级公立国考手册 | H19: 门诊使用基本药物人次数/同期门诊诊疗总人次数*100
A20: 住院患者基本药物使用率 | B20: % | C20: 药学部 | D20: 95.58 | E20: 94.31 | F20: 91.2 | G20: 详见三级中医、三级公立国考手册 | H20: 出院患者使用基本药物总人次数/同期出院总人次数*100
A21: 基本药物采购品种数占比 | B21: % | C21: 药学部 | D21: 46.43 | E21: 41.41 | F21: 40.02 | G21: 详见三级中医、三级公立国考手册 | H21: 医院采购基本药物品种数/医院同期采购药物品种总数*100
A22: 国家组织药品集中采购中标药品金额占比 | B22: % | C22: 药学部 | D22: 87.09 | E22: 48.46 | F22: 0 | G22: 详见三级中医、三级公立国考手册 | H22: 中标药品用量/同种药品用量*100
A23: 重点监控高值医用耗材收入占比 | B23: % | C23: 设备科 | D23: 35.8021 | E23: 35.8758 | F23: 39.7873 | G23: 详见国考手册 | H23: 重点监控高值医用耗材收入/同期卫生材料收入*100
A24: 门诊患者平均预约诊疗率 | B24: % | C24: 门诊部 | D24: 100 | E24: 98.74 | F24: 89.59 | G24: 详见三级中医、三级公立国考手册 | H24: 预约诊疗人次数/总诊疗人次数*100
A25: 门诊患者预约后平均等待时间 | B25: 分钟 | C25: 门诊部 | D25: 19.52 | E25: 23.56 | F25: 24.53 | G25: 26.52 | H25: ∑{进入诊室诊疗的时钟时间-到达分诊台或通过信息系统（自助机、APP等）报到的时钟时间}/预约诊疗人次数
A26: 电子病历应用功能水平分级 | B26: 级别 | C26: 信息科 | D26: 4 | E26: 4 | F26: 3 | G26: 详见国考手册
A27: 平均住院日 | B27: 天 | C27: 统计室 | D27: 7.59 | E27: 7.91 | F27: 8.3 | G27: 详见二级公立国考手册 | H27: 出院患者占用总床日数/同期出院患者人数
A28: CMI值 | C28: 质控科 | D28: 1.29 | E28: 1.31 | F28: 1.24 | G28: 病例组合指数
A29: DRGs组数 | B29: 组 | C29: 质控科 | D29: 752 | E29: 745 | F29: 746 | G29: 诊断相关分组组数
A30: 每百张病床药师人数 | B30: 人 | C30: 人事科 | D30: 3.18 | E30: 3.31 | F30: 2.48 | G30: 详见三级中医、三级公立国考手册 | H30: 医院药师（包括药剂师和临床药师）总人数/医院实际开放床位数*100
A31: 核定床位数 | B31: 张 | C31: 统计室 | D31: 2500 | E31: 2500 | F31: 2500 | G31: 等级评审标准细则
A32: 实际开放床位数 | B32: 张 | C32: 统计室 | D32: 2800 | E32: 2570 | F32: 2818 | G32: 等级评审标准细则
A33: 开放床位使用率 | B33: % | C33: 统计室 | D33: 96.21 | E33: 96.23 | F33: 102.3 | G33: 等级评审标准细则 | H33: 实际占用的总床日数/同期实际开放的总床日数*100
A34: 卫生技术人员数与开放床位数比 | C34: 人事科 | D34: =2806/D32 -> 1.0021429 | E34: =2806/E32 -> 1.0918288 | F34: =2806/F32 -> 0.99574166 | G34: 等级评审标准细则，原计量单位为比值（1:X），现改为小数 | H34: 医院卫生技术人员数/同期全院实际开放床位数
A35: 医师人数与开放床位数比 | C35: 人事科 | D35: =D60/D32 -> 0.27214286 | E35: =E60/E32 -> 0.28171206 | F35: =F60/F32 -> 0.24733854 | G35: 等级评审标准细则，原计量单位为比值（1:X），现改为小数 | H35: 医院执业（助理）医师总数/同期全院实际开放床位数
A36: 护士人数与开放床位数比 | C36: 人事科 | D36: =D61/D32 -> 0.62178571 | E36: =E61/E32 -> 0.67782101 | F36: =F61/F32 -> 0.61107168 | G36: 等级评审标准细则，原计量单位为比值（1:X），现改为小数 | H36: 医院注册护士总数/同期全院实际开放床位数
A37: 人均医疗服务收入 | B37: 万元 | C37: 财务科 | D37: 16.29 | E37: 14.73 | F37: 16.19 | G37: 按科室人员数人均医疗服务收入
A38: 人均有效收入 | B38: 万元 | C38: 财务科 | D38: 32.71 | E38: 29.78 | F38: 30.71 | G38: 按科室人员数人均有效收入
A39: 床均医疗服务收入 | B39: 万元 | C39: 财务科 | D39: 21.37 | E39: 19.03 | F39: 19.68 | G39: 按开放床位数床均医疗服务收入
A40: 床均有效收入 | B40: 万元 | C40: 财务科 | D40: 42.93 | E40: 38.47 | F40: 37.32 | G40: 按开放床位数床均有效收入
...

Sheet 大心血管科
A1: 数据名 | B1: 计量单位 | C1: 填报部门 | D1: Y2021 | E1: Y2020 | F1: Y2019 | G1: 指标说明 | H1: 计算公式
A2: 出院患者手术占比 | B2: % | C2: 统计室 | D2: 23.190294 | E2: 21.178184 | F2: 17.842007 | G2: 详见三级公立、二级公立国考手册。举例：30%请填写30（不带百分号），而非写成30%，或0.3。下同 | H2: 出院患者手术台次数/同期出院患者总人次数*100
A3: 出院患者微创手术占比 | B3: % | C3: 统计室 | D3: 0.3511236 | E3: 0.64488392 | F3: 0.14251781 | G3: 详见三级公立、二级公立国考手册 | H3: 出院患者微创手术台次数/同期出院患者手术台次数*100
A4: 出院患者四级手术比例 | B4: % | C4: 统计室 | D4: 12.113764 | E4: 10.83405 | F4: 10.831354 | G4: 详见三级公立国考手册 | H4: 出院患者四级手术台次数/同期出院患者手术台次数*100
A5: 出院患者疑难危重病例比例 | B5: % | C5: 统计室 | D5: 99.63 | E5: 99.695 | F5: 98.625 | G5: 即CD型病例占比 | H5: (疑难病例数+危重病例数)/出院人数*100
A6: 手术患者并发症发生率 | B6: % | C6: 质控科 | D6: 0 | E6: 0 | F6: 0 | G6: 详见国考手册 | H6: 手术患者并发症发生例数/同期出院的手术患者人数*100
A7: I类切口手术部位感染率 | B7: % | C7: 质控科 | D7: 0.03 | E7: 0 | F7: 0.04 | G7: 详见三级中医、三级公立国考手册 | H7: I类切口手术部位感染人次数/同期I类切口手术台次数*100
A8: 大型医用设备检查阳性率 | B8: % | C8: 医务科 | G8: 详见三级中医、三级公立国考手册 | H8: 大型医用设备检查阳性数/同期大型医用设备检查人次数*100
A9: 低风险组病例死亡率 | B9: % | C9: 质控科 | D9: 0 | E9: 0 | F9: 0 | G9: 详见三级公立、二级公立国考手册 | H9: 低风险组死亡例数/低风险组病例数*100
A10: 医院感染发生率 | B10: % | C10: 院感科 | D10: 0.37 | E10: 0.55 | F10: 0.7 | G10: 等级评审标准细则
A11: 抗菌药物使用强度DDDs | B11: DDD | C11: 药学部 | D11: 39.832876 | E11: 40.162805 | F11: 35.158241 | G11: 详见国考手册 | H11: 住院患者抗菌药物消耗量（累计DDD数）/同期收治患者人天数*100
A12: 门诊患者基本药物处方占比 | B12: % | C12: 药学部 | D12: 93.115 | E12: 90.49 | F12: 74.075 | G12: 详见三级中医、三级公立国考手册 | H12: 门诊使用基本药物人次数/同期门诊诊疗总人次数*100
A13: 住院患者基本药物使用率 | B13: % | C13: 药学部 | D13: 99.1 | E13: 99.325 | F13: 96.275 | G13: 详见三级中医、三级公立国考手册 | H13: 出院患者使用基本药物总人次数/同期出院总人次数*100
A14: 重点监控高值医用耗材收入占比 | B14: % | C14: 设备科 | D14: =0.1058*100 -> 10.58 | E14: =33130822/(110206952+20678422)*100 -> 25.312853 | F14: =(23470061+4478610)/(128922725+20353525)*100 -> 18.722785 | G14: 详见国考手册 | H14: 重点监控高值医用耗材收入/同期卫生材料收入*100
A15: 平均住院日 | B15: 天 | C15: 统计室 | D15: 8.33 | E15: 8.235 | F15: 8.06 | G15: 详见二级公立国考手册 | H15: 出院患者占用总床日数/同期出院患者人数
A16: CMI值 | C16: 质控科 | G16: 病例组合指数
A17: DRGs组数 | B17: 组 | C17: 质控科 | G17: 诊断相关分组组数
A18: 核定床位数 | B18: 张 | C18: 统计室 | D18: 206 | E18: 206 | F18: 206 | G18: 等级评审标准细则
A19: 实际开放床位数 | B19: 张 | C19: 统计室 | D19: 220 | E19: 196 | F19: 238 | G19: 等级评审标准细则
A20: 开放床位使用率 | B20: % | C20: 统计室 | D20: 102.33 | E20: 88.415 | F20: 95.9 | G20: 等级评审标准细则 | H20: 实际占用的总床日数/同期实际开放的总床日数*100
A21: 医师人数与开放床位数比 | C21: 人事科 | D21: =D43/D19 -> 0.2 | E21: =E43/E19 -> 0.20408163 | F21: =F43/F19 -> 0.15966387 | G21: 等级评审标准细则，原计量单位为比值（1:X），现改为小数 | H21: 医院执业（助理）医师总数/同期全院实际开放床位数
A22: 护士人数与开放床位数比 | C22: 人事科 | D22: =D44/D19 -> 0.48181818 | E22: =E44/E19 -> 0.53061224 | F22: =F44/F19 -> 0.44117647 | G22: 等级评审标准细则，原计量单位为比值（1:X），现改为小数 | H22: 医院注册护士总数/同期全院实际开放床位数
A23: 人均医疗服务收入 | B23: 万元 | C23: 财务科 | D23: 25.570819 | E23: 21.989401 | F23: 22.94347 | G23: 按科室人员数人均医疗服务收入
A24: 人均有效收入 | B24: 万元 | C24: 财务科 | D24: 51.782776 | E24: 46.304564 | F24: 47.216788 | G24: 按科室人员数人均有效收入
A25: 床均医疗服务收入 | B25: 万元 | C25: 财务科 | D25: 19.891496 | E25: 16.060124 | F25: 15.038577 | G25: 按开放床位数床均医疗服务收入
A26: 床均有效收入 | B26: 万元 | C26: 财务科 | D26: 40.281731 | E26: 33.818884 | F26: 30.948819 | G26: 按开放床位数床均有效收入
A27: 每名执业医师日均住院工作负担 | B27: 床日 | C27: 财务科 | D27: 4.8405978 | E27: 4.9060959 | F27: 5.9886806 | G27: 详见三级中医、三级公立国考手册 | H27: 全年实际占用总床日数/医院平均执业(助理)医师人数/365
A28: 医疗服务收入占医疗收入比例 | B28: % | C28: 财务科 | D28: 27.979896 | E28: 25.497914 | F28: 23.070673 | G28: 参考国考手册，原指标名为：医疗服务收入（不含药品、耗材、检查检验收入）占医疗收入比例 | H28: 医疗服务收入/医疗收入*100
A29: 医疗收入 | B29: 万元 | C29: 财务科 | D29: 15079.345 | E29: 13884.641 | F29: 15513.987 | H29: 门诊收入+住院收入
A30: 医疗服务收入 | B30: 万元 | C30: 财务科 | D30: 4219.1851 | E30: 3540.2936 | F30: 3579.1813
A31: 有效收入 | B31: 万元 | C31: 财务科 | D31: 8544.158 | E31: 7455.0347 | F31: 7365.8189 | H31: 医疗服务收入+检查检验收入
A32: 医疗直接成本 | B32: 万元 | D32: 11031.86 | E32: 10317.21 | F32: 11857.84
A33: 收支结余率 | B33: % | D33: -2.32 | E33: -2 | F33: -0.7
A34: 万元收入能耗占比 | B34: 吨标煤/万元 | C34: 后勤管理科 | G34: 详见国考手册 | H34: 年总能耗/年总收入*10000
A35: 门诊收入占医疗收入比例 | B35: % | C35: 财务科 | D35: 9.5830879 | E35: 8.5848501 | F35: 8.4682459 | G35: 详见三级公立国考手册 | H35: 门诊收入/医疗收入*100
A36: 住院收入占医疗收入比例 | B36: % | C36: 财务科 | D36: 90.416912 | E36: 91.41515 | F36: 91.531754 | G36: 详见三级公立国考手册 | H36: 住院收入/医疗收入*100
A37: 医疗收入增幅 | B37: % | C37: 财务科 | D37: 8.6045048 | E37: -10.502436 | F37: 0.22085775 | G37: 详见国考手册 | H37: （本年度医疗收入－上一年度医疗收入）/上一年度医疗收入*100
A38: 门诊次均费用增幅 | B38: % | C38: 财务科 | D38: -1.8092926 | E38: -7.1418152 | F38: 4.2073907 | G38: 详见国考手册 | H38: （本年度门诊患者次均医药费用－上一年度门诊患者次均医药费用）/上一年度门诊患者次均医药费用*100
A39: 住院次均费用增幅 | B39: % | C39: 财务科 | D39: -3.9421621 | E39: -15.060851 | F39: -9.2614934 | G39: 详见国考手册 | H39: （本年度出院患者次均医药费用－上一年度出院患者次均医药费用）/上一年度出院患者次均医药费用*100
A40: 门诊次均药品费用增幅 | B40: % | C40: 财务科 | D40: -1.1297645 | E40: -17.143776 | F40: 8.3875733 | G40: 详见国考手册 | H40: （本年度门诊患者次均药品费用－上一年度门诊患者次均药品费用）/上一年度门诊患者次均药品费用*100
...

Sheet 心血管内科
A1: 数据名 | B1: 计量单位 | C1: 填报部门 | D1: Y2021 | E1: Y2020 | F1: Y2019 | G1: 指标说明 | H1: 计算公式
A2: 出院患者手术占比 | B2: % | C2: 统计室 | D2: 21.647609 | E2: 19.818164 | F2: 16.767933 | G2: 详见三级公立、二级公立国考手册。举例：30%请填写30（不带百分号），而非写成30%，或0.3。下同 | H2: 出院患者手术台次数/同期出院患者总人次数*100
A3: 出院患者微创手术占比 | B3: % | C3: 统计室 | D3: 0.12004802 | E3: 0.048804295 | F3: 0.10816658 | G3: 详见三级公立、二级公立国考手册 | H3: 出院患者微创手术台次数/同期出院患者手术台次数*100
A4: 出院患者四级手术比例 | B4: % | C4: 统计室 | D4: 1.5206082 | E4: 0.9272816 | F4: 1.2439156 | G4: 详见三级公立国考手册 | H4: 出院患者四级手术台次数/同期出院患者手术台次数*100
A5: 出院患者疑难危重病例比例 | B5: % | C5: 统计室 | D5: 99.4 | E5: 99.39 | F5: 98.29 | G5: 即CD型病例占比 | H5: (疑难病例数+危重病例数)/出院人数*100
A6: 手术患者并发症发生率 | B6: % | C6: 质控科 | D6: 0 | E6: 0 | F6: 0 | G6: 详见国考手册 | H6: 手术患者并发症发生例数/同期出院的手术患者人数*100
A7: I类切口手术部位感染率 | B7: % | C7: 质控科 | D7: 0 | E7: 0 | F7: 0.04 | G7: 详见三级中医、三级公立国考手册 | H7: I类切口手术部位感染人次数/同期I类切口手术台次数*100
A8: 大型医用设备检查阳性率 | B8: % | C8: 医务科 | G8: 详见三级中医、三级公立国考手册 | H8: 大型医用设备检查阳性数/同期大型医用设备检查人次数*100
A9: 低风险组病例死亡率 | B9: % | C9: 质控科 | D9: 0 | E9: 0 | F9: 0 | G9: 详见三级公立、二级公立国考手册 | H9: 低风险组死亡例数/低风险组病例数*100
A10: 医院感染发生率 | B10: % | C10: 院感科 | D10: 0.34 | E10: 0.44 | F10: 0.66 | G10: 等级评审标准细则
A11: 抗菌药物使用强度DDDs | B11: DDD | C11: 药学部 | D11: 18.210171 | E11: 17.582223 | F11: 16.975232 | G11: 详见国考手册 | H11: 住院患者抗菌药物消耗量（累计DDD数）/同期收治患者人天数*100
A12: 门诊患者基本药物处方占比 | B12: % | C12: 药学部 | D12: 95.78 | E12: 89.86 | F12: 72.1 | G12: 详见三级中医、三级公立国考手册 | H12: 门诊使用基本药物人次数/同期门诊诊疗总人次数*100
A13: 住院患者基本药物使用率 | B13: % | C13: 药学部 | D13: 99.46 | E13: 99.29 | F13: 96.79 | G13: 详见三级中医、三级公立国考手册 | H13: 出院患者使用基本药物总人次数/同期出院总人次数*100
A14: 重点监控高值医用耗材收入占比 | B14: % | C14: 设备科 | D14: =(7764647+1000339)/118547152*100 -> 7.3936707 | E14: =32920822/110206952*100 -> 29.87182 | F14: =23470061/128922725*100 -> 18.204751 | G14: 详见国考手册 | H14: 重点监控高值医用耗材收入/同期卫生材料收入*100
A15: 平均住院日 | B15: 天 | C15: 统计室 | D15: 6.16 | E15: 6.4 | F15: 6.92 | G15: 详见二级公立国考手册 | H15: 出院患者占用总床日数/同期出院患者人数
A16: CMI值 | C16: 质控科 | D16: 1.57 | E16: 1.49 | F16: 1.43 | G16: 病例组合指数
A17: DRGs组数 | B17: 组 | C17: 质控科 | D17: 279 | E17: 251 | F17: 267 | G17: 诊断相关分组组数
A18: 核定床位数 | B18: 张 | C18: 统计室 | D18: 190 | E18: 190 | F18: 190 | G18: 等级评审标准细则
A19: 实际开放床位数 | B19: 张 | C19: 统计室 | D19: 203 | E19: 180 | F19: 220 | G19: 等级评审标准细则
A20: 开放床位使用率 | B20: % | C20: 统计室 | D20: 100.06 | E20: 88.85 | F20: 95.57 | G20: 等级评审标准细则 | H20: 实际占用的总床日数/同期实际开放的总床日数*100
A21: 医师人数与开放床位数比 | C21: 人事科 | D21: =D43/D19 -> 0.1773399 | E21: =E43/E19 -> 0.18888889 | F21: =F43/F19 -> 0.15454545 | G21: 等级评审标准细则，原计量单位为比值（1:X），现改为小数 | H21: 医院执业（助理）医师总数/同期全院实际开放床位数
A22: 护士人数与开放床位数比 | C22: 人事科 | D22: =D44/D19 -> 0.52216749 | E22: =E44/E19 -> 0.57777778 | F22: =F44/F19 -> 0.47727273 | G22: 等级评审标准细则，原计量单位为比值（1:X），现改为小数 | H22: 医院注册护士总数/同期全院实际开放床位数
A23: 人均医疗服务收入 | B23: 万元 | C23: 财务科 | D23: 23.810493 | E23: 19.38115 | F23: 21.21953 | G23: 按科室人员数人均医疗服务收入
A24: 人均有效收入 | B24: 万元 | C24: 财务科 | D24: 50.321795 | E24: 42.692755 | F24: 45.31541 | G24: 按科室人员数人均有效收入
A25: 床均医疗服务收入 | B25: 万元 | C25: 财务科 | D25: 18.518189 | E25: 14.873373 | F25: 14.082051 | G25: 按开放床位数床均医疗服务收入
A26: 床均有效收入 | B26: 万元 | C26: 财务科 | D26: 39.136885 | E26: 32.763035 | F26: 30.072954 | G26: 按开放床位数床均有效收入
A27: 每名执业医师日均住院工作负担 | B27: 床日 | C27: 财务科 | D27: 5.4318874 | E27: 5.3265109 | F27: 6.1838034 | G27: 详见三级中医、三级公立国考手册 | H27: 全年实际占用总床日数/医院平均执业(助理)医师人数/365
A28: 医疗服务收入占医疗收入比例 | B28: % | C28: 财务科 | D28: 28.995036 | E28: 25.908957 | F28: 23.142359 | G28: 参考国考手册，原指标名为：医疗服务收入（不含药品、耗材、检查检验收入）占医疗收入比例 | H28: 医疗服务收入/医疗收入*100
A29: 医疗收入 | B29: 万元 | C29: 财务科 | D29: 12482.119 | E29: 11669.552 | F29: 13386.929 | H29: 门诊收入+住院收入
A30: 医疗服务收入 | B30: 万元 | C30: 财务科 | D30: 3619.1949 | E30: 3023.4593 | F30: 3098.0513
A31: 有效收入 | B31: 万元 | C31: 财务科 | D31: 7648.9129 | E31: 6660.0699 | F31: 6616.0499 | H31: 医疗服务收入+检查检验收入
A32: 医疗直接成本 | B32: 万元 | D32: 9349.11 | E32: 8863.6 | F32: 10579.01
A33: 收支结余率 | B33: % | D33: -6.87 | E33: -6.94 | F33: -5.48
A34: 万元收入能耗占比 | B34: 吨标煤/万元 | C34: 后勤管理科 | G34: 详见国考手册 | H34: 年总能耗/年总收入*10000
A35: 门诊收入占医疗收入比例 | B35: % | C35: 财务科 | D35: 10.850673 | E35: 9.5636458 | F35: 9.4331297 | G35: 详见三级公立国考手册 | H35: 门诊收入/医疗收入*100
A36: 住院收入占医疗收入比例 | B36: % | C36: 财务科 | D36: 89.149327 | E36: 90.436354 | F36: 90.56687 | G36: 详见三级公立国考手册 | H36: 住院收入/医疗收入*100
A37: 医疗收入增幅 | B37: % | C37: 财务科 | D37: 6.9631344 | E37: -12.82876 | F37: -0.38687462 | G37: 详见国考手册 | H37: （本年度医疗收入－上一年度医疗收入）/上一年度医疗收入*100
A38: 门诊次均费用增幅 | B38: % | C38: 财务科 | D38: -2.1723017 | E38: -9.3341584 | F38: 3.5656335 | G38: 详见国考手册 | H38: （本年度门诊患者次均医药费用－上一年度门诊患者次均医药费用）/上一年度门诊患者次均医药费用*100
A39: 住院次均费用增幅 | B39: % | C39: 财务科 | D39: -6.0050248 | E39: -6.6986242 | F39: -6.437672 | G39: 详见国考手册 | H39: （本年度出院患者次均医药费用－上一年度出院患者次均医药费用）/上一年度出院患者次均医药费用*100
A40: 门诊次均药品费用增幅 | B40: % | C40: 财务科 | D40: -3.1239045 | E40: -17.851685 | F40: 7.5957336 | G40: 详见国考手册 | H40: （本年度门诊患者次均药品费用－上一年度门诊患者次均药品费用）/上一年度门诊患者次均药品费用*100
...

Sheet 心脏外科
A1: 数据名 | B1: 计量单位 | C1: 填报部门 | D1: Y2021 | E1: Y2020 | F1: Y2019 | G1: 指标说明 | H1: 计算公式
A2: 出院患者手术占比 | B2: % | C2: 统计室 | D2: 47.354138 | E2: 43.012422 | F2: 33.203632 | G2: 详见三级公立、二级公立国考手册。举例：30%请填写30（不带百分号），而非写成30%，或0.3。下同 | H2: 出院患者手术台次数/同期出院患者总人次数*100
A3: 出院患者微创手术占比 | B3: % | C3: 统计室 | D3: 2.0057307 | E3: 5.0541516 | F3: 0.390625 | G3: 详见三级公立、二级公立国考手册 | H3: 出院患者微创手术台次数/同期出院患者手术台次数*100
A4: 出院患者四级手术比例 | B4: % | C4: 统计室 | D4: 87.965616 | E4: 84.115523 | F4: 80.078125 | G4: 详见三级公立国考手册 | H4: 出院患者四级手术台次数/同期出院患者手术台次数*100
A5: 出院患者疑难危重病例比例 | B5: % | C5: 统计室 | D5: 99.86 | E5: 100 | F5: 98.96 | G5: 即CD型病例占比 | H5: (疑难病例数+危重病例数)/出院人数*100
A6: 手术患者并发症发生率 | B6: % | C6: 质控科 | D6: 0 | E6: 0 | F6: 0 | G6: 详见国考手册 | H6: 手术患者并发症发生例数/同期出院的手术患者人数*100
A7: I类切口手术部位感染率 | B7: % | C7: 质控科 | D7: 0.26 | E7: 0 | F7: 0 | G7: 详见三级中医、三级公立国考手册 | H7: I类切口手术部位感染人次数/同期I类切口手术台次数*100
A8: 大型医用设备检查阳性率 | B8: % | C8: 医务科 | G8: 详见三级中医、三级公立国考手册 | H8: 大型医用设备检查阳性数/同期大型医用设备检查人次数*100
A9: 低风险组病例死亡率 | B9: % | C9: 质控科 | D9: 0 | E9: 0 | F9: 0 | G9: 详见三级公立、二级公立国考手册 | H9: 低风险组死亡例数/低风险组病例数*100
A10: 医院感染发生率 | B10: % | C10: 院感科 | D10: 0.93 | E10: 2.21 | F10: 1.28 | G10: 等级评审标准细则
A11: 抗菌药物使用强度DDDs | B11: DDD | C11: 药学部 | D11: 61.455581 | E11: 62.743386 | F11: 53.34125 | G11: 详见国考手册 | H11: 住院患者抗菌药物消耗量（累计DDD数）/同期收治患者人天数*100
A12: 门诊患者基本药物处方占比 | B12: % | C12: 药学部 | D12: 90.45 | E12: 91.12 | F12: 76.05 | G12: 详见三级中医、三级公立国考手册 | H12: 门诊使用基本药物人次数/同期门诊诊疗总人次数*100
A13: 住院患者基本药物使用率 | B13: % | C13: 药学部 | D13: 98.74 | E13: 99.36 | F13: 95.76 | G13: 详见三级中医、三级公立国考手册 | H13: 出院患者使用基本药物总人次数/同期出院总人次数*100
A14: 重点监控高值医用耗材收入占比 | B14: % | C14: 设备科 | D14: =(5416100+771120)/22790299*100 -> 27.148481 | E14: =5640850/20678422*100 -> 27.278919 | F14: =4478610/20353525*100 -> 22.0041 | G14: 详见国考手册 | H14: 重点监控高值医用耗材收入/同期卫生材料收入*100
A15: 平均住院日 | B15: 天 | C15: 统计室 | D15: 10.5 | E15: 10.07 | F15: 9.2 | G15: 详见二级公立国考手册 | H15: 出院患者占用总床日数/同期出院患者人数
A16: CMI值 | C16: 质控科 | D16: 4.43 | E16: 4.11 | F16: 3.25 | G16: 病例组合指数
A17: DRGs组数 | B17: 组 | C17: 质控科 | D17: 80 | E17: 73 | F17: 84 | G17: 诊断相关分组组数
A18: 核定床位数 | B18: 张 | C18: 统计室 | D18: 16 | E18: 16 | F18: 16 | G18: 等级评审标准细则
A19: 实际开放床位数 | B19: 张 | C19: 统计室 | D19: 17 | E19: 16 | F19: 18 | G19: 等级评审标准细则
A20: 开放床位使用率 | B20: % | C20: 统计室 | D20: 104.6 | E20: 87.98 | F20: 96.23 | G20: 等级评审标准细则 | H20: 实际占用的总床日数/同期实际开放的总床日数*100
A21: 医师人数与开放床位数比 | C21: 人事科 | D21: =D43/D19 -> 0.41176471 | E21: =E43/E19 -> 0.375 | F21: =F43/F19 -> 0.22222222 | G21: 等级评审标准细则，原计量单位为比值（1:X），现改为小数 | H21: 医院执业（助理）医师总数/同期全院实际开放床位数
A22: 护士人数与开放床位数比 | C22: 人事科 | D22: =D44/D19 -> 1.2352941 | E22: =E44/E19 -> 1.0625 | F22: =F44/F19 -> 0.94444444 | G22: 等级评审标准细则，原计量单位为比值（1:X），现改为小数 | H22: 医院注册护士总数/同期全院实际开放床位数
A23: 人均医疗服务收入 | B23: 万元 | C23: 财务科 | D23: 46.153092 | E23: 103.36686 | F23: 48.112997 | G23: 按科室人员数人均医疗服务收入
A24: 人均有效收入 | B24: 万元 | C24: 财务科 | D24: 68.865008 | E24: 158.99298 | F24: 74.976901 | G24: 按科室人员数人均有效收入
A25: 床均医疗服务收入 | B25: 万元 | C25: 财务科 | D25: 35.992213 | E25: 30.118549 | F25: 26.729443 | G25: 按开放床位数床均医疗服务收入
A26: 床均有效收入 | B26: 万元 | C26: 财务科 | D26: 53.703966 | E26: 46.326626 | F26: 41.653834 | G26: 按开放床位数床均有效收入
A27: 每名执业医师日均住院工作负担 | B27: 床日 | C27: 财务科 | D27: 2.4911937 | E27: 2.5237443 | F27: 4.330137 | G27: 详见三级中医、三级公立国考手册 | H27: 全年实际占用总床日数/医院平均执业(助理)医师人数/365
A28: 医疗服务收入占医疗收入比例 | B28: % | C28: 财务科 | D28: 23.101193 | E28: 23.332449 | F28: 22.619509 | G28: 参考国考手册，原指标名为：医疗服务收入（不含药品、耗材、检查检验收入）占医疗收入比例 | H28: 医疗服务收入/医疗收入*100
A29: 医疗收入 | B29: 万元 | C29: 财务科 | D29: 2597.226 | E29: 2215.0881 | F29: 2127.0576 | H29: 门诊收入+住院收入
A30: 医疗服务收入 | B30: 万元 | C30: 财务科 | D30: 599.99019 | E30: 516.8343 | F30: 481.12997
A31: 有效收入 | B31: 万元 | C31: 财务科 | D31: 895.24511 | E31: 794.96489 | F31: 749.76901 | H31: 医疗服务收入+检查检验收入
A32: 医疗直接成本 | B32: 万元 | D32: 1682.75 | E32: 1453.6 | F32: 1278.83
A33: 收支结余率 | B33: % | D33: 26.3 | E33: 24.07 | F33: 22.3
A34: 万元收入能耗占比 | B34: 吨标煤/万元 | C34: 后勤管理科 | G34: 详见国考手册 | H34: 年总能耗/年总收入*10000
A35: 门诊收入占医疗收入比例 | B35: % | C35: 财务科 | D35: 3.4911444 | E35: 3.4283475 | F35: 2.3956174 | G35: 详见三级公立国考手册 | H35: 门诊收入/医疗收入*100
A36: 住院收入占医疗收入比例 | B36: % | C36: 财务科 | D36: 96.508856 | E36: 96.571653 | F36: 97.604383 | G36: 详见三级公立国考手册 | H36: 住院收入/医疗收入*100
A37: 医疗收入增幅 | B37: % | C37: 财务科 | D37: 17.251591 | E37: 4.1386036 | F37: 4.2226989 | G37: 详见国考手册 | H37: （本年度医疗收入－上一年度医疗收入）/上一年度医疗收入*100
A38: 门诊次均费用增幅 | B38: % | C38: 财务科 | D38: 2.2728365 | E38: 48.359273 | F38: 15.967105 | G38: 详见国考手册 | H38: （本年度门诊患者次均医药费用－上一年度门诊患者次均医药费用）/上一年度门诊患者次均医药费用*100
A39: 住院次均费用增幅 | B39: % | C39: 财务科 | D39: 6.1698802 | E39: 28.929786 | F39: -6.6898599 | G39: 详见国考手册 | H39: （本年度出院患者次均医药费用－上一年度出院患者次均医药费用）/上一年度出院患者次均医药费用*100
A40: 门诊次均药品费用增幅 | B40: % | C40: 财务科 | D40: 65.422451 | E40: 37.34942 | F40: 48.422107 | G40: 详见国考手册 | H40: （本年度门诊患者次均药品费用－上一年度门诊患者次均药品费用）/上一年度门诊患者次均药品费用*100
...

Sheet 大骨科
A1: 数据名 | B1: 计量单位 | C1: 填报部门 | D1: Y2021 | E1: Y2020 | F1: Y2019 | G1: 指标说明 | H1: 计算公式
A2: 出院患者手术占比 | B2: % | C2: 统计室 | D2: 76.167845 | E2: 65.829617 | F2: 65.526631 | G2: 详见三级公立、二级公立国考手册。举例：30%请填写30（不带百分号），而非写成30%，或0.3。下同 | H2: 出院患者手术台次数/同期出院患者总人次数*100
A3: 出院患者微创手术占比 | B3: % | C3: 统计室 | D3: 10.348501 | E3: 7.5579323 | F3: 7.5964096 | G3: 详见三级公立、二级公立国考手册 | H3: 出院患者微创手术台次数/同期出院患者手术台次数*100
A4: 出院患者四级手术比例 | B4: % | C4: 统计室 | D4: 33.389134 | E4: 31.247772 | F4: 31.100399 | G4: 详见三级公立国考手册 | H4: 出院患者四级手术台次数/同期出院患者手术台次数*100
A5: 出院患者疑难危重病例比例 | B5: % | C5: 统计室 | D5: 95.196667 | E5: 85.523333 | F5: 79.603333 | G5: 即CD型病例占比 | H5: (疑难病例数+危重病例数)/出院人数*100
A6: 手术患者并发症发生率 | B6: % | C6: 质控科 | D6: 0 | E6: 0 | F6: 0 | G6: 详见国考手册 | H6: 手术患者并发症发生例数/同期出院的手术患者人数*100
A7: I类切口手术部位感染率 | B7: % | C7: 质控科 | D7: 0.21 | E7: 0.27 | F7: 0.23 | G7: 详见三级中医、三级公立国考手册 | H7: I类切口手术部位感染人次数/同期I类切口手术台次数*100
A8: 大型医用设备检查阳性率 | B8: % | C8: 医务科 | G8: 详见三级中医、三级公立国考手册 | H8: 大型医用设备检查阳性数/同期大型医用设备检查人次数*100
A9: 低风险组病例死亡率 | B9: % | C9: 质控科 | D9: 0 | E9: 0 | F9: 0 | G9: 详见三级公立、二级公立国考手册 | H9: 低风险组死亡例数/低风险组病例数*100
A10: 医院感染发生率 | B10: % | C10: 院感科 | D10: 1.03 | E10: 1.01 | F10: 0.8 | G10: 等级评审标准细则
A11: 抗菌药物使用强度DDDs | B11: DDD | C11: 药学部 | D11: 45.186613 | E11: 48.461146 | F11: 45.132843 | G11: 详见国考手册 | H11: 住院患者抗菌药物消耗量（累计DDD数）/同期收治患者人天数*100
A12: 门诊患者基本药物处方占比 | B12: % | C12: 药学部 | D12: 79.2 | E12: 71.096667 | F12: 67.34 | G12: 详见三级中医、三级公立国考手册 | H12: 门诊使用基本药物人次数/同期门诊诊疗总人次数*100
A13: 住院患者基本药物使用率 | B13: % | C13: 药学部 | D13: 97.863333 | E13: 96.55 | F13: 95.336667 | G13: 详见三级中医、三级公立国考手册 | H13: 出院患者使用基本药物总人次数/同期出院总人次数*100
A14: 重点监控高值医用耗材收入占比 | B14: % | C14: 设备科 | D14: =(34041302.4+5049693)/(61030488+52314296+34657840)*100 -> 26.412366 | E14: =40248949/(59638630+52373450+30035598)*100 -> 28.334817 | F14: =(22522726+5321361+5301602)/(67539684+56858658+33233253)*100 -> 21.027313 | G14: 详见国考手册 | H14: 重点监控高值医用耗材收入/同期卫生材料收入*100
A15: 平均住院日 | B15: 天 | C15: 统计室 | D15: 9.5 | E15: 9.6433333 | F15: 10.486667 | G15: 详见二级公立国考手册 | H15: 出院患者占用总床日数/同期出院患者人数
A16: CMI值 | C16: 质控科 | G16: 病例组合指数
A17: DRGs组数 | B17: 组 | C17: 质控科 | G17: 诊断相关分组组数
A18: 核定床位数 | B18: 张 | C18: 统计室 | D18: 214 | E18: 214 | F18: 214 | G18: 等级评审标准细则
A19: 实际开放床位数 | B19: 张 | C19: 统计室 | D19: 249 | E19: 214 | F19: 275 | G19: 等级评审标准细则
A20: 开放床位使用率 | B20: % | C20: 统计室 | D20: 94.276667 | E20: 89.743333 | F20: 96.3 | G20: 等级评审标准细则 | H20: 实际占用的总床日数/同期实际开放的总床日数*100
A21: 医师人数与开放床位数比 | C21: 人事科 | D21: =D43/D19 -> 0.13253012 | E21: =E43/E19 -> 0.14953271 | F21: =F43/F19 -> 0.11636364 | G21: 等级评审标准细则，原计量单位为比值（1:X），现改为小数 | H21: 医院执业（助理）医师总数/同期全院实际开放床位数
A22: 护士人数与开放床位数比 | C22: 人事科 | D22: =D44/D19 -> 0.43373494 | E22: =E44/E19 -> 0.55607477 | F22: =F44/F19 -> 0.44 | G22: 等级评审标准细则，原计量单位为比值（1:X），现改为小数 | H22: 医院注册护士总数/同期全院实际开放床位数
A23: 人均医疗服务收入 | B23: 万元 | C23: 财务科 | D23: 35.704502 | E23: 32.307204 | F23: 33.120738 | G23: 按科室人员数人均医疗服务收入
A24: 人均有效收入 | B24: 万元 | C24: 财务科 | D24: 60.182548 | E24: 56.493334 | F24: 56.63798 | G24: 按科室人员数人均有效收入
A25: 床均医疗服务收入 | B25: 万元 | C25: 财务科 | D25: 23.152525 | E25: 20.200095 | F25: 19.631565 | G25: 按开放床位数床均医疗服务收入
A26: 床均有效收入 | B26: 万元 | C26: 财务科 | D26: 39.025274 | E26: 35.322485 | F26: 33.570875 | G26: 按开放床位数床均有效收入
A27: 每名执业医师日均住院工作负担 | B27: 床日 | C27: 财务科 | D27: 6.8298049 | E27: 7.0974315 | F27: 8.2855308 | G27: 详见三级中医、三级公立国考手册 | H27: 全年实际占用总床日数/医院平均执业(助理)医师人数/365
A28: 医疗服务收入占医疗收入比例 | B28: % | C28: 财务科 | D28: 33.605564 | E28: 33.20553 | F28: 32.881393 | G28: 参考国考手册，原指标名为：医疗服务收入（不含药品、耗材、检查检验收入）占医疗收入比例 | H28: 医疗服务收入/医疗收入*100
A29: 医疗收入 | B29: 万元 | C29: 财务科 | D29: 16361.854 | E29: 15177.965 | F29: 16418.649 | H29: 门诊收入+住院收入
A30: 医疗服务收入 | B30: 万元 | C30: 财务科 | D30: 5498.4933 | E30: 5039.9238 | F30: 5398.6803
A31: 有效收入 | B31: 万元 | C31: 财务科 | D31: 9268.1124 | E31: 8812.9601 | F31: 9231.9907 | H31: 医疗服务收入+检查检验收入
A32: 医疗直接成本 | B32: 万元 | D32: 11799.24 | E32: 9924.36 | F32: 11373.22
A33: 收支结余率 | B33: % | D33: 3.26 | E33: 7.14 | F33: 2.18
A34: 万元收入能耗占比 | B34: 吨标煤/万元 | C34: 后勤管理科 | G34: 详见国考手册 | H34: 年总能耗/年总收入*10000
A35: 门诊收入占医疗收入比例 | B35: % | C35: 财务科 | D35: 8.7814786 | E35: 7.7745092 | F35: 7.0768024 | G35: 详见三级公立国考手册 | H35: 门诊收入/医疗收入*100
A36: 住院收入占医疗收入比例 | B36: % | C36: 财务科 | D36: 91.218521 | E36: 92.225491 | F36: 92.923198 | G36: 详见三级公立国考手册 | H36: 住院收入/医疗收入*100
A37: 医疗收入增幅 | B37: % | C37: 财务科 | D37: 7.800047 | E37: -7.556549 | F37: 12.625806 | G37: 详见国考手册 | H37: （本年度医疗收入－上一年度医疗收入）/上一年度医疗收入*100
A38: 门诊次均费用增幅 | B38: % | C38: 财务科 | D38: 2.7962866 | E38: 2.347993 | F38: -66.956926 | G38: 详见国考手册 | H38: （本年度门诊患者次均医药费用－上一年度门诊患者次均医药费用）/上一年度门诊患者次均医药费用*100
A39: 住院次均费用增幅 | B39: % | C39: 财务科 | D39: 6.6463008 | E39: -2.066098 | F39: 19.28938 | G39: 详见国考手册 | H39: （本年度出院患者次均医药费用－上一年度出院患者次均医药费用）/上一年度出院患者次均医药费用*100
A40: 门诊次均药品费用增幅 | B40: % | C40: 财务科 | D40: 5.2522104 | E40: -3.733806 | F40: -63.011532 | G40: 详见国考手册 | H40: （本年度门诊患者次均药品费用－上一年度门诊患者次均药品费用）/上一年度门诊患者次均药品费用*100
...

Sheet 脊柱外科
A1: 数据名 | B1: 计量单位 | C1: 填报部门 | D1: Y2021 | E1: Y2020 | F1: Y2019 | G1: 指标说明 | H1: 计算公式
A2: 出院患者手术占比 | B2: % | C2: 统计室 | D2: 57.256236 | E2: 44.429018 | F2: 45.683802 | G2: 详见三级公立、二级公立国考手册。举例：30%请填写30（不带百分号），而非写成30%，或0.3。下同 | H2: 出院患者手术台次数/同期出院患者总人次数*100
A3: 出院患者微创手术占比 | B3: % | C3: 统计室 | D3: 8.3168317 | E3: 5.546875 | F3: 4.8124558 | G3: 详见三级公立、二级公立国考手册 | H3: 出院患者微创手术台次数/同期出院患者手术台次数*100
A4: 出院患者四级手术比例 | B4: % | C4: 统计室 | D4: 89.50495 | E4: 89.140625 | F4: 85.704176 | G4: 详见三级公立国考手册 | H4: 出院患者四级手术台次数/同期出院患者手术台次数*100
A5: 出院患者疑难危重病例比例 | B5: % | C5: 统计室 | D5: 95.88 | E5: 97.71 | F5: 89.3 | G5: 即CD型病例占比 | H5: (疑难病例数+危重病例数)/出院人数*100
A6: 手术患者并发症发生率 | B6: % | C6: 质控科 | D6: 0 | E6: 0 | F6: 0 | G6: 详见国考手册 | H6: 手术患者并发症发生例数/同期出院的手术患者人数*100
A7: I类切口手术部位感染率 | B7: % | C7: 质控科 | D7: 0.32 | E7: 0.37 | F7: 0.2 | G7: 详见三级中医、三级公立国考手册 | H7: I类切口手术部位感染人次数/同期I类切口手术台次数*100
A8: 大型医用设备检查阳性率 | B8: % | C8: 医务科 | G8: 详见三级中医、三级公立国考手册 | H8: 大型医用设备检查阳性数/同期大型医用设备检查人次数*100
A9: 低风险组病例死亡率 | B9: % | C9: 质控科 | D9: 0 | E9: 0 | F9: 0 | G9: 详见三级公立、二级公立国考手册 | H9: 低风险组死亡例数/低风险组病例数*100
A10: 医院感染发生率 | B10: % | C10: 院感科 | D10: 1.63 | E10: 1.63 | F10: 0.9 | G10: 等级评审标准细则
A11: 抗菌药物使用强度DDDs | B11: DDD | C11: 药学部 | D11: 35.718693 | E11: 38.509554 | F11: 33.14572 | G11: 详见国考手册 | H11: 住院患者抗菌药物消耗量（累计DDD数）/同期收治患者人天数*100
A12: 门诊患者基本药物处方占比 | B12: % | C12: 药学部 | D12: 83.22 | E12: 80.97 | F12: 72.79 | G12: 详见三级中医、三级公立国考手册 | H12: 门诊使用基本药物人次数/同期门诊诊疗总人次数*100
A13: 住院患者基本药物使用率 | B13: % | C13: 药学部 | D13: 97.55 | E13: 96.96 | F13: 94.87 | G13: 详见三级中医、三级公立国考手册 | H13: 出院患者使用基本药物总人次数/同期出院总人次数*100
A14: 重点监控高值医用耗材收入占比 | B14: % | C14: 设备科 | D14: =(15295843.6+2398085)/61030488*100 -> 28.99195 | E14: =20544757/59638630*100 -> 34.448741 | F14: =22522726/67539684*100 -> 33.347396 | G14: 详见国考手册 | H14: 重点监控高值医用耗材收入/同期卫生材料收入*100
A15: 平均住院日 | B15: 天 | C15: 统计室 | D15: 10.38 | E15: 10.23 | F15: 10.57 | G15: 详见二级公立国考手册 | H15: 出院患者占用总床日数/同期出院患者人数
A16: CMI值 | C16: 质控科 | D16: 2.15 | E16: 1.84 | F16: 1.88 | G16: 病例组合指数
A17: DRGs组数 | B17: 组 | C17: 质控科 | D17: 85 | E17: 94 | F17: 91 | G17: 诊断相关分组组数
A18: 核定床位数 | B18: 张 | C18: 统计室 | D18: 80 | E18: 80 | F18: 80 | G18: 等级评审标准细则
A19: 实际开放床位数 | B19: 张 | C19: 统计室 | D19: 97 | E19: 80 | F19: 110 | G19: 等级评审标准细则
A20: 开放床位使用率 | B20: % | C20: 统计室 | D20: 83.94 | E20: 82.61 | F20: 81.92 | G20: 等级评审标准细则 | H20: 实际占用的总床日数/同期实际开放的总床日数*100
A21: 医师人数与开放床位数比 | C21: 人事科 | D21: =D43/D19 -> 0.092783505 | E21: =E43/E19 -> 0.1125 | F21: =F43/F19 -> 0.072727273 | G21: 等级评审标准细则，原计量单位为比值（1:X），现改为小数 | H21: 医院执业（助理）医师总数/同期全院实际开放床位数
A22: 护士人数与开放床位数比 | C22: 人事科 | D22: =D44/D19 -> 0.3814433 | E22: =E44/E19 -> 0.5625 | F22: =F44/F19 -> 0.40909091 | G22: 等级评审标准细则，原计量单位为比值（1:X），现改为小数 | H22: 医院注册护士总数/同期全院实际开放床位数
A23: 人均医疗服务收入 | B23: 万元 | C23: 财务科 | D23: 40.349086 | E23: 34.834736 | F23: 37.713232 | G23: 按科室人员数人均医疗服务收入
A24: 人均有效收入 | B24: 万元 | C24: 财务科 | D24: 69.927297 | E24: 65.061471 | F24: 66.822795 | G24: 按科室人员数人均有效收入
A25: 床均医疗服务收入 | B25: 万元 | C25: 财务科 | D25: 23.394613 | E25: 20.015855 | F25: 19.542311 | G25: 按开放床位数床均医疗服务收入
A26: 床均有效收入 | B26: 万元 | C26: 财务科 | D26: 40.544215 | E26: 37.383977 | F26: 34.626357 | G26: 按开放床位数床均有效收入
A27: 每名执业医师日均住院工作负担 | B27: 床日 | C27: 财务科 | D27: 8.525723 | E27: 8.9704718 | F27: 11.264384 | G27: 详见三级中医、三级公立国考手册 | H27: 全年实际占用总床日数/医院平均执业(助理)医师人数/365
A28: 医疗服务收入占医疗收入比例 | B28: % | C28: 财务科 | D28: 31.826415 | E28: 30.652236 | F28: 30.630897 | G28: 参考国考手册，原指标名为：医疗服务收入（不含药品、耗材、检查检验收入）占医疗收入比例 | H28: 医疗服务收入/医疗收入*100
A29: 医疗收入 | B29: 万元 | C29: 财务科 | D29: 6719.2664 | E29: 6364.1206 | F29: 7017.9278 | H29: 门诊收入+住院收入
A30: 医疗服务收入 | B30: 万元 | C30: 财务科 | D30: 2138.5016 | E30: 1950.7452 | F30: 2149.6542
A31: 有效收入 | B31: 万元 | C31: 财务科 | D31: 3706.1467 | E31: 3643.4424 | F31: 3808.8993 | H31: 医疗服务收入+检查检验收入
A32: 医疗直接成本 | B32: 万元 | D32: 4511.2 | E32: 4025.45 | F32: 4499.61
A33: 收支结余率 | B33: % | D33: 13.83 | E33: 13.38 | F33: 11.48
A34: 万元收入能耗占比 | B34: 吨标煤/万元 | C34: 后勤管理科 | G34: 详见国考手册 | H34: 年总能耗/年总收入*10000
A35: 门诊收入占医疗收入比例 | B35: % | C35: 财务科 | D35: 9.0991142 | E35: 8.3279932 | F35: 7.2850811 | G35: 详见三级公立国考手册 | H35: 门诊收入/医疗收入*100
A36: 住院收入占医疗收入比例 | B36: % | C36: 财务科 | D36: 90.900886 | E36: 91.672007 | F36: 92.714919 | G36: 详见三级公立国考手册 | H36: 住院收入/医疗收入*100
A37: 医疗收入增幅 | B37: % | C37: 财务科 | D37: 5.5804384 | E37: -9.3162437 | F37: 36.829274 | G37: 详见国考手册 | H37: （本年度医疗收入－上一年度医疗收入）/上一年度医疗收入*100
A38: 门诊次均费用增幅 | B38: % | C38: 财务科 | D38: 5.8087673 | E38: -1.6785888 | F38: -59.507961 | G38: 详见国考手册 | H38: （本年度门诊患者次均医药费用－上一年度门诊患者次均医药费用）/上一年度门诊患者次均医药费用*100
A39: 住院次均费用增幅 | B39: % | C39: 财务科 | D39: 11.76881 | E39: -3.1372301 | F39: 42.223666 | G39: 详见国考手册 | H39: （本年度出院患者次均医药费用－上一年度出院患者次均医药费用）/上一年度出院患者次均医药费用*100
A40: 门诊次均药品费用增幅 | B40: % | C40: 财务科 | D40: 16.336403 | E40: -6.9633366 | F40: -55.237157 | G40: 详见国考手册 | H40: （本年度门诊患者次均药品费用－上一年度门诊患者次均药品费用）/上一年度门诊患者次均药品费用*100
...

Sheet 创伤骨科
A1: 数据名 | B1: 计量单位 | C1: 填报部门 | D1: Y2021 | E1: Y2020 | F1: Y2019 | G1: 指标说明 | H1: 计算公式
A2: 出院患者手术占比 | B2: % | C2: 统计室 | D2: 84.929757 | E2: 76.529822 | F2: 76.154618 | G2: 详见三级公立、二级公立国考手册。举例：30%请填写30（不带百分号），而非写成30%，或0.3。下同 | H2: 出院患者手术台次数/同期出院患者总人次数*100
A3: 出院患者微创手术占比 | B3: % | C3: 统计室 | D3: 1.4736842 | E3: 0.60728745 | F3: 0.92287409 | G3: 详见三级公立、二级公立国考手册 | H3: 出院患者微创手术台次数/同期出院患者手术台次数*100
A4: 出院患者四级手术比例 | B4: % | C4: 统计室 | D4: 5.2330827 | E4: 1.0458839 | F4: 1.3513514 | G4: 详见三级公立国考手册 | H4: 出院患者四级手术台次数/同期出院患者手术台次数*100
A5: 出院患者疑难危重病例比例 | B5: % | C5: 统计室 | D5: 94.89 | E5: 75.83 | F5: 69.8 | G5: 即CD型病例占比 | H5: (疑难病例数+危重病例数)/出院人数*100
A6: 手术患者并发症发生率 | B6: % | C6: 质控科 | D6: 0 | E6: 0 | F6: 0 | G6: 详见国考手册 | H6: 手术患者并发症发生例数/同期出院的手术患者人数*100
A7: I类切口手术部位感染率 | B7: % | C7: 质控科 | D7: 0.2 | E7: 0.05 | F7: 0.29 | G7: 详见三级中医、三级公立国考手册 | H7: I类切口手术部位感染人次数/同期I类切口手术台次数*100
A8: 大型医用设备检查阳性率 | B8: % | C8: 医务科 | G8: 详见三级中医、三级公立国考手册 | H8: 大型医用设备检查阳性数/同期大型医用设备检查人次数*100
A9: 低风险组病例死亡率 | B9: % | C9: 质控科 | D9: 0 | E9: 0 | F9: 0 | G9: 详见三级公立、二级公立国考手册 | H9: 低风险组死亡例数/低风险组病例数*100
A10: 医院感染发生率 | B10: % | C10: 院感科 | D10: 0.87 | E10: 0.67 | F10: 0.9 | G10: 等级评审标准细则
A11: 抗菌药物使用强度DDDs | B11: DDD | C11: 药学部 | D11: 68.260528 | E11: 70.134053 | F11: 70.25339 | G11: 详见国考手册 | H11: 住院患者抗菌药物消耗量（累计DDD数）/同期收治患者人天数*100
A12: 门诊患者基本药物处方占比 | B12: % | C12: 药学部 | D12: 78.87 | E12: 72.16 | F12: 68.79 | G12: 详见三级中医、三级公立国考手册 | H12: 门诊使用基本药物人次数/同期门诊诊疗总人次数*100
A13: 住院患者基本药物使用率 | B13: % | C13: 药学部 | D13: 98.6 | E13: 96.79 | F13: 95.8 | G13: 详见三级中医、三级公立国考手册 | H13: 出院患者使用基本药物总人次数/同期出院总人次数*100
A14: 重点监控高值医用耗材收入占比 | B14: % | C14: 设备科 | D14: =(10462203+1179040)/52314296*100 -> 22.252508 | E14: =9599104/52373450*100 -> 18.328187 | F14: =5321361/56858658*100 -> 9.3589282 | G14: 详见国考手册 | H14: 重点监控高值医用耗材收入/同期卫生材料收入*100
A15: 平均住院日 | B15: 天 | C15: 统计室 | D15: 10.25 | E15: 9.95 | F15: 11.55 | G15: 详见二级公立国考手册 | H15: 出院患者占用总床日数/同期出院患者人数
A16: CMI值 | C16: 质控科 | D16: 1.58 | E16: 1.4 | F16: 1.49 | G16: 病例组合指数
A17: DRGs组数 | B17: 组 | C17: 质控科 | D17: 133 | E17: 146 | F17: 149 | G17: 诊断相关分组组数
A18: 核定床位数 | B18: 张 | C18: 统计室 | D18: 94 | E18: 94 | F18: 94 | G18: 等级评审标准细则
A19: 实际开放床位数 | B19: 张 | C19: 统计室 | D19: 103 | E19: 94 | F19: 110 | G19: 等级评审标准细则
A20: 开放床位使用率 | B20: % | C20: 统计室 | D20: 105.7 | E20: 100.85 | F20: 111.25 | G20: 等级评审标准细则 | H20: 实际占用的总床日数/同期实际开放的总床日数*100
A21: 医师人数与开放床位数比 | C21: 人事科 | D21: =D43/D19 -> 0.15533981 | E21: =E43/E19 -> 0.18085106 | F21: =F43/F19 -> 0.13636364 | G21: 等级评审标准细则，原计量单位为比值（1:X），现改为小数 | H21: 医院执业（助理）医师总数/同期全院实际开放床位数
A22: 护士人数与开放床位数比 | C22: 人事科 | D22: =D44/D19 -> 0.47572816 | E22: =E44/E19 -> 0.54255319 | F22: =F44/F19 -> 0.45454545 | G22: 等级评审标准细则，原计量单位为比值（1:X），现改为小数 | H22: 医院注册护士总数/同期全院实际开放床位数
A23: 人均医疗服务收入 | B23: 万元 | C23: 财务科 | D23: 31.482536 | E23: 31.30081 | F23: 31.376036 | G23: 按科室人员数人均医疗服务收入
A24: 人均有效收入 | B24: 万元 | C24: 财务科 | D24: 50.790221 | E24: 51.612046 | F24: 49.728532 | G24: 按科室人员数人均有效收入
A25: 床均医疗服务收入 | B25: 万元 | C25: 财务科 | D25: 21.399564 | E25: 19.996646 | F25: 19.966568 | G25: 按开放床位数床均医疗服务收入
A26: 床均有效收入 | B26: 万元 | C26: 财务科 | D26: 34.523541 | E26: 32.972559 | F26: 31.64543 | G26: 按开放床位数床均有效收入
A27: 每名执业医师日均住院工作负担 | B27: 床日 | C27: 财务科 | D27: 6.6077055 | E27: 6.1455278 | F27: 8.1579909 | G27: 详见三级中医、三级公立国考手册 | H27: 全年实际占用总床日数/医院平均执业(助理)医师人数/365
A28: 医疗服务收入占医疗收入比例 | B28: % | C28: 财务科 | D28: 36.978335 | E28: 36.652478 | F28: 36.828963 | G28: 参考国考手册，原指标名为：医疗服务收入（不含药品、耗材、检查检验收入）占医疗收入比例 | H28: 医疗服务收入/医疗收入*100
A29: 医疗收入 | B29: 万元 | C29: 财务科 | D29: 5789.3694 | E29: 5636.3269 | F29: 5963.5741 | H29: 门诊收入+住院收入
A30: 医疗服务收入 | B30: 万元 | C30: 财务科 | D30: 2140.8124 | E30: 2065.8535 | F30: 2196.3225
A31: 有效收入 | B31: 万元 | C31: 财务科 | D31: 3453.735 | E31: 3406.395 | F31: 3480.9973 | H31: 医疗服务收入+检查检验收入
A32: 医疗直接成本 | B32: 万元 | D32: 4583.68 | E32: 3671.92 | F32: 3977.79
A33: 收支结余率 | B33: % | D33: -0.8 | E33: 1.76 | F33: -12.58
A34: 万元收入能耗占比 | B34: 吨标煤/万元 | C34: 后勤管理科 | G34: 详见国考手册 | H34: 年总能耗/年总收入*10000
A35: 门诊收入占医疗收入比例 | B35: % | C35: 财务科 | D35: 6.2751173 | E35: 5.344615 | F35: 4.921211 | G35: 详见三级公立国考手册 | H35: 门诊收入/医疗收入*100
A36: 住院收入占医疗收入比例 | B36: % | C36: 财务科 | D36: 93.724883 | E36: 94.655385 | F36: 95.078789 | G36: 详见三级公立国考手册 | H36: 住院收入/医疗收入*100
A37: 医疗收入增幅 | B37: % | C37: 财务科 | D37: 2.7152888 | E37: -5.487434 | F37: -1.8271884 | G37: 详见国考手册 | H37: （本年度医疗收入－上一年度医疗收入）/上一年度医疗收入*100
A38: 门诊次均费用增幅 | B38: % | C38: 财务科 | D38: 0.14773991 | E38: 6.5845257 | F38: -80.314729 | G38: 详见国考手册 | H38: （本年度门诊患者次均医药费用－上一年度门诊患者次均医药费用）/上一年度门诊患者次均医药费用*100
A39: 住院次均费用增幅 | B39: % | C39: 财务科 | D39: 3.5098375 | E39: -5.0579291 | F39: 1.9116855 | G39: 详见国考手册 | H39: （本年度出院患者次均医药费用－上一年度出院患者次均医药费用）/上一年度出院患者次均医药费用*100
A40: 门诊次均药品费用增幅 | B40: % | C40: 财务科 | D40: 9.01097 | E40: -6.2946889 | F40: -81.656571 | G40: 详见国考手册 | H40: （本年度门诊患者次均药品费用－上一年度门诊患者次均药品费用）/上一年度门诊患者次均药品费用*100
...

Sheet 关节骨病科
A1: 数据名 | B1: 计量单位 | C1: 填报部门 | D1: Y2021 | E1: Y2020 | F1: Y2019 | G1: 指标说明 | H1: 计算公式
A2: 出院患者手术占比 | B2: % | C2: 统计室 | D2: 84.929757 | E2: 76.529822 | F2: 76.154618 | G2: 详见三级公立、二级公立国考手册。举例：30%请填写30（不带百分号），而非写成30%，或0.3。下同 | H2: 出院患者手术台次数/同期出院患者总人次数*100
A3: 出院患者微创手术占比 | B3: % | C3: 统计室 | D3: 1.4736842 | E3: 0.60728745 | F3: 0.92287409 | G3: 详见三级公立、二级公立国考手册 | H3: 出院患者微创手术台次数/同期出院患者手术台次数*100
A4: 出院患者四级手术比例 | B4: % | C4: 统计室 | D4: 5.2330827 | E4: 1.0458839 | F4: 1.3513514 | G4: 详见三级公立国考手册 | H4: 出院患者四级手术台次数/同期出院患者手术台次数*100
A5: 出院患者疑难危重病例比例 | B5: % | C5: 统计室 | D5: 94.89 | E5: 75.83 | F5: 69.8 | G5: 即CD型病例占比 | H5: (疑难病例数+危重病例数)/出院人数*100
A6: 手术患者并发症发生率 | B6: % | C6: 质控科 | D6: 0 | E6: 0 | F6: 0 | G6: 详见国考手册 | H6: 手术患者并发症发生例数/同期出院的手术患者人数*100
A7: I类切口手术部位感染率 | B7: % | C7: 质控科 | D7: 0.2 | E7: 0.05 | F7: 0.29 | G7: 详见三级中医、三级公立国考手册 | H7: I类切口手术部位感染人次数/同期I类切口手术台次数*100
A8: 大型医用设备检查阳性率 | B8: % | C8: 医务科 | G8: 详见三级中医、三级公立国考手册 | H8: 大型医用设备检查阳性数/同期大型医用设备检查人次数*100
A9: 低风险组病例死亡率 | B9: % | C9: 质控科 | D9: 0 | E9: 0 | F9: 0 | G9: 详见三级公立、二级公立国考手册 | H9: 低风险组死亡例数/低风险组病例数*100
A10: 医院感染发生率 | B10: % | C10: 院感科 | D10: 0.87 | E10: 0.67 | F10: 0.9 | G10: 等级评审标准细则
A11: 抗菌药物使用强度DDDs | B11: DDD | C11: 药学部 | D11: 68.260528 | E11: 70.134053 | F11: 70.25339 | G11: 详见国考手册 | H11: 住院患者抗菌药物消耗量（累计DDD数）/同期收治患者人天数*100
A12: 门诊患者基本药物处方占比 | B12: % | C12: 药学部 | D12: 78.87 | E12: 72.16 | F12: 68.79 | G12: 详见三级中医、三级公立国考手册 | H12: 门诊使用基本药物人次数/同期门诊诊疗总人次数*100
A13: 住院患者基本药物使用率 | B13: % | C13: 药学部 | D13: 98.6 | E13: 96.79 | F13: 95.8 | G13: 详见三级中医、三级公立国考手册 | H13: 出院患者使用基本药物总人次数/同期出院总人次数*100
A14: 重点监控高值医用耗材收入占比 | B14: % | C14: 设备科 | D14: =(8283256.5+1472568)/34657840*100 -> 28.148969 | E14: =10105088/30034498*100 -> 33.644937 | F14: =5301602/33233253*100 -> 15.952703 | G14: 详见国考手册 | H14: 重点监控高值医用耗材收入/同期卫生材料收入*100
A15: 平均住院日 | B15: 天 | C15: 统计室 | D15: 10.25 | E15: 9.95 | F15: 11.55 | G15: 详见二级公立国考手册 | H15: 出院患者占用总床日数/同期出院患者人数
A16: CMI值 | C16: 质控科 | D16: 1.58 | E16: 1.4 | F16: 1.49 | G16: 病例组合指数
A17: DRGs组数 | B17: 组 | C17: 质控科 | D17: 133 | E17: 146 | F17: 149 | G17: 诊断相关分组组数
A18: 核定床位数 | B18: 张 | C18: 统计室 | D18: 94 | E18: 94 | F18: 94 | G18: 等级评审标准细则
A19: 实际开放床位数 | B19: 张 | C19: 统计室 | D19: 49 | E19: 40 | F19: 55 | G19: 等级评审标准细则
A20: 开放床位使用率 | B20: % | C20: 统计室 | D20: 105.7 | E20: 100.85 | F20: 111.25 | G20: 等级评审标准细则 | H20: 实际占用的总床日数/同期实际开放的总床日数*100
A21: 医师人数与开放床位数比 | C21: 人事科 | D21: =D43/D19 -> 0.32653061 | E21: =E43/E19 -> 0.425 | F21: =F43/F19 -> 0.27272727 | G21: 等级评审标准细则，原计量单位为比值（1:X），现改为小数 | H21: 医院执业（助理）医师总数/同期全院实际开放床位数
A22: 护士人数与开放床位数比 | C22: 人事科 | D22: =D44/D19 -> 1 | E22: =E44/E19 -> 1.275 | F22: =F44/F19 -> 0.90909091 | G22: 等级评审标准细则，原计量单位为比值（1:X），现改为小数 | H22: 医院注册护士总数/同期全院实际开放床位数
A23: 人均医疗服务收入 | B23: 万元 | C23: 财务科 | D23: 31.482536 | E23: 31.30081 | F23: 31.376036 | G23: 按科室人员数人均医疗服务收入
A24: 人均有效收入 | B24: 万元 | C24: 财务科 | D24: 50.790221 | E24: 51.612046 | F24: 49.728532 | G24: 按科室人员数人均有效收入
A25: 床均医疗服务收入 | B25: 万元 | C25: 财务科 | D25: 21.399564 | E25: 19.996646 | F25: 19.966568 | G25: 按开放床位数床均医疗服务收入
A26: 床均有效收入 | B26: 万元 | C26: 财务科 | D26: 34.523541 | E26: 32.972559 | F26: 31.64543 | G26: 按开放床位数床均有效收入
A27: 每名执业医师日均住院工作负担 | B27: 床日 | C27: 财务科 | D27: 6.6077055 | E27: 6.1455278 | F27: 8.1579909 | G27: 详见三级中医、三级公立国考手册 | H27: 全年实际占用总床日数/医院平均执业(助理)医师人数/365
A28: 医疗服务收入占医疗收入比例 | B28: % | C28: 财务科 | D28: 36.978335 | E28: 36.652478 | F28: 36.828963 | G28: 参考国考手册，原指标名为：医疗服务收入（不含药品、耗材、检查检验收入）占医疗收入比例 | H28: 医疗服务收入/医疗收入*100
A29: 医疗收入 | B29: 万元 | C29: 财务科 | D29: 5789.3694 | E29: 5636.3269 | F29: 5963.5741 | H29: 门诊收入+住院收入
A30: 医疗服务收入 | B30: 万元 | C30: 财务科 | D30: 2140.8124 | E30: 2065.8535 | F30: 2196.3225
A31: 有效收入 | B31: 万元 | C31: 财务科 | D31: 3453.735 | E31: 3406.395 | F31: 3480.9973 | H31: 医疗服务收入+检查检验收入
A32: 医疗直接成本 | B32: 万元 | D32: 2704.35 | E32: 2226.99 | F32: 2895.82
A33: 收支结余率 | B33: % | D33: -11.29 | E33: 4.19 | F33: 8.16
A34: 万元收入能耗占比 | B34: 吨标煤/万元 | C34: 后勤管理科 | G34: 详见国考手册 | H34: 年总能耗/年总收入*10000
A35: 门诊收入占医疗收入比例 | B35: % | C35: 财务科 | D35: 6.2751173 | E35: 5.344615 | F35: 4.921211 | G35: 详见三级公立国考手册 | H35: 门诊收入/医疗收入*100
A36: 住院收入占医疗收入比例 | B36: % | C36: 财务科 | D36: 93.724883 | E36: 94.655385 | F36: 95.078789 | G36: 详见三级公立国考手册 | H36: 住院收入/医疗收入*100
A37: 医疗收入增幅 | B37: % | C37: 财务科 | D37: 2.7152888 | E37: -5.487434 | F37: -1.8271884 | G37: 详见国考手册 | H37: （本年度医疗收入－上一年度医疗收入）/上一年度医疗收入*100
A38: 门诊次均费用增幅 | B38: % | C38: 财务科 | D38: 0.14773991 | E38: 6.5845257 | F38: -80.314729 | G38: 详见国考手册 | H38: （本年度门诊患者次均医药费用－上一年度门诊患者次均医药费用）/上一年度门诊患者次均医药费用*100
A39: 住院次均费用增幅 | B39: % | C39: 财务科 | D39: 3.5098375 | E39: -5.0579291 | F39: 1.9116855 | G39: 详见国考手册 | H39: （本年度出院患者次均医药费用－上一年度出院患者次均医药费用）/上一年度出院患者次均医药费用*100
A40: 门诊次均药品费用增幅 | B40: % | C40: 财务科 | D40: 9.01097 | E40: -6.2946889 | F40: -81.656571 | G40: 详见国考手册 | H40: （本年度门诊患者次均药品费用－上一年度门诊患者次均药品费用）/上一年度门诊患者次均药品费用*100
...

Sheet 妇科
A1: 数据名 | B1: 计量单位 | C1: 填报部门 | D1: Y2021 | E1: Y2020 | F1: Y2019 | G1: 指标说明 | H1: 计算公式
A2: 出院患者手术占比 | B2: % | C2: 统计室 | D2: 71.521246 | E2: 66.066351 | F2: 65.272727 | G2: 详见三级公立、二级公立国考手册。举例：30%请填写30（不带百分号），而非写成30%，或0.3。下同 | H2: 出院患者手术台次数/同期出院患者总人次数*100
A3: 出院患者微创手术占比 | B3: % | C3: 统计室 | D3: 65.170068 | E3: 64.08417 | F3: 64.623955 | G3: 详见三级公立、二级公立国考手册 | H3: 出院患者微创手术台次数/同期出院患者手术台次数*100
A4: 出院患者四级手术比例 | B4: % | C4: 统计室 | D4: 40.589569 | E4: 41.415591 | F4: 37.558032 | G4: 详见三级公立国考手册 | H4: 出院患者四级手术台次数/同期出院患者手术台次数*100
A5: 出院患者疑难危重病例比例 | B5: % | C5: 统计室 | D5: 99.32 | E5: 98.01 | F5: 93.73 | G5: 即CD型病例占比 | H5: (疑难病例数+危重病例数)/出院人数*100
A6: 手术患者并发症发生率 | B6: % | C6: 质控科 | D6: 0 | E6: 0 | F6: 0 | G6: 详见国考手册 | H6: 手术患者并发症发生例数/同期出院的手术患者人数*100
A7: I类切口手术部位感染率 | B7: % | C7: 质控科 | D7: 0 | E7: 0 | F7: 0 | G7: 详见三级中医、三级公立国考手册 | H7: I类切口手术部位感染人次数/同期I类切口手术台次数*100
A8: 大型医用设备检查阳性率 | B8: % | C8: 医务科 | G8: 详见三级中医、三级公立国考手册 | H8: 大型医用设备检查阳性数/同期大型医用设备检查人次数*100
A9: 低风险组病例死亡率 | B9: % | C9: 质控科 | D9: 0 | E9: 0 | F9: 0 | G9: 详见三级公立、二级公立国考手册 | H9: 低风险组死亡例数/低风险组病例数*100
A10: 医院感染发生率 | B10: % | C10: 院感科 | D10: 0.1 | E10: 0.25 | F10: 0.55 | G10: 等级评审标准细则
A11: 抗菌药物使用强度DDDs | B11: DDD | C11: 药学部 | D11: 65.305947 | E11: 67.274962 | F11: 53.561583 | G11: 详见国考手册 | H11: 住院患者抗菌药物消耗量（累计DDD数）/同期收治患者人天数*100
A12: 门诊患者基本药物处方占比 | B12: % | C12: 药学部 | D12: 97.46 | E12: 86.69 | F12: 79.12 | G12: 详见三级中医、三级公立国考手册 | H12: 门诊使用基本药物人次数/同期门诊诊疗总人次数*100
A13: 住院患者基本药物使用率 | B13: % | C13: 药学部 | D13: 92.77 | E13: 92.01 | F13: 95.35 | G13: 详见三级中医、三级公立国考手册 | H13: 出院患者使用基本药物总人次数/同期出院总人次数*100
A14: 重点监控高值医用耗材收入占比 | B14: % | C14: 设备科 | D14: =1080/51499757*100 -> 0.0020970973 | E14: =1512/52054773*100 -> 0.0029046328 | F14: =3528/57189813*100 -> 0.0061689308 | G14: 详见国考手册 | H14: 重点监控高值医用耗材收入/同期卫生材料收入*100
A15: 平均住院日 | B15: 天 | C15: 统计室 | D15: 5.51 | E15: 5.56 | F15: 6.23 | G15: 详见二级公立国考手册 | H15: 出院患者占用总床日数/同期出院患者人数
A16: CMI值 | C16: 质控科 | D16: 1.17 | E16: 1.13 | F16: 1.14 | G16: 病例组合指数
A17: DRGs组数 | B17: 组 | C17: 质控科 | D17: 72 | E17: 69 | F17: 81 | G17: 诊断相关分组组数
A18: 核定床位数 | B18: 张 | C18: 统计室 | D18: 49 | E18: 49 | F18: 49 | G18: 等级评审标准细则
A19: 实际开放床位数 | B19: 张 | C19: 统计室 | D19: 55 | E19: 49 | F19: 60 | G19: 等级评审标准细则
A20: 开放床位使用率 | B20: % | C20: 统计室 | D20: 87.12 | E20: 86.95 | F20: 94.88 | G20: 等级评审标准细则 | H20: 实际占用的总床日数/同期实际开放的总床日数*100
A21: 医师人数与开放床位数比 | C21: 人事科 | D21: =D43/D19 -> 0.34545455 | E21: =E43/E19 -> 0.36734694 | F21: =F43/F19 -> 0.28333333 | G21: 等级评审标准细则，原计量单位为比值（1:X），现改为小数 | H21: 医院执业（助理）医师总数/同期全院实际开放床位数
A22: 护士人数与开放床位数比 | C22: 人事科 | D22: =D44/D19 -> 0.78181818 | E22: =E44/E19 -> 0.91836735 | F22: =F44/F19 -> 0.73333333 | G22: 等级评审标准细则，原计量单位为比值（1:X），现改为小数 | H22: 医院注册护士总数/同期全院实际开放床位数
A23: 人均医疗服务收入 | B23: 万元 | C23: 财务科 | D23: 31.096024 | E23: 34.975719 | F23: 31.497223 | G23: 按科室人员数人均医疗服务收入
A24: 人均有效收入 | B24: 万元 | C24: 财务科 | D24: 66.039754 | E24: 72.704035 | F24: 67.43082 | G24: 按科室人员数人均有效收入
A25: 床均医疗服务收入 | B25: 万元 | C25: 财务科 | D25: 40.4606 | E25: 37.87984 | F25: 37.271714 | G25: 按开放床位数床均医疗服务收入
A26: 床均有效收入 | B26: 万元 | C26: 财务科 | D26: 85.927645 | E26: 78.740832 | F26: 79.793138 | G26: 按开放床位数床均有效收入
A27: 每名执业医师日均住院工作负担 | B27: 床日 | C27: 财务科 | D27: 2.4315789 | E27: 2.6835616 | F27: 3.3485898 | G27: 详见三级中医、三级公立国考手册 | H27: 全年实际占用总床日数/医院平均执业(助理)医师人数/365
A28: 医疗服务收入占医疗收入比例 | B28: % | C28: 财务科 | D28: 40.198723 | E28: 40.954099 | F28: 39.560647 | G28: 参考国考手册，原指标名为：医疗服务收入（不含药品、耗材、检查检验收入）占医疗收入比例 | H28: 医疗服务收入/医疗收入*100
A29: 医疗收入 | B29: 万元 | C29: 财务科 | D29: 5337.5467 | E29: 5124.1347 | F29: 5652.8469 | H29: 门诊收入+住院收入
A30: 医疗服务收入 | B30: 万元 | C30: 财务科 | D30: 2145.6256 | E30: 2098.5432 | F30: 2236.3028
A31: 有效收入 | B31: 万元 | C31: 财务科 | D31: 4556.743 | E31: 4362.2421 | F31: 4787.5883 | H31: 医疗服务收入+检查检验收入
A32: 医疗直接成本 | B32: 万元 | D32: 3083.38 | E32: 2642.69 | F32: 2882.95
A33: 收支结余率 | B33: % | D33: 26 | E33: 26.3 | F33: 19.66
A34: 万元收入能耗占比 | B34: 吨标煤/万元 | C34: 后勤管理科 | G34: 详见国考手册 | H34: 年总能耗/年总收入*10000
A35: 门诊收入占医疗收入比例 | B35: % | C35: 财务科 | D35: 43.923369 | E35: 40.761308 | F35: 43.142719 | G35: 详见三级公立国考手册 | H35: 门诊收入/医疗收入*100
A36: 住院收入占医疗收入比例 | B36: % | C36: 财务科 | D36: 56.076631 | E36: 59.238692 | F36: 56.857281 | G36: 详见三级公立国考手册 | H36: 住院收入/医疗收入*100
A37: 医疗收入增幅 | B37: % | C37: 财务科 | D37: 4.1648412 | E37: -9.3530268 | F37: 19.065351 | G37: 详见国考手册 | H37: （本年度医疗收入－上一年度医疗收入）/上一年度医疗收入*100
A38: 门诊次均费用增幅 | B38: % | C38: 财务科 | D38: -0.49770391 | E38: 2.0812188 | F38: 7.330144 | G38: 详见国考手册 | H38: （本年度门诊患者次均医药费用－上一年度门诊患者次均医药费用）/上一年度门诊患者次均医药费用*100
A39: 住院次均费用增幅 | B39: % | C39: 财务科 | D39: 2.1683849 | E39: -0.66867654 | F39: 4.3485981 | G39: 详见国考手册 | H39: （本年度出院患者次均医药费用－上一年度出院患者次均医药费用）/上一年度出院患者次均医药费用*100
A40: 门诊次均药品费用增幅 | B40: % | C40: 财务科 | D40: 12.019418 | E40: 6.2848418 | F40: 20.843788 | G40: 详见国考手册 | H40: （本年度门诊患者次均药品费用－上一年度门诊患者次均药品费用）/上一年度门诊患者次均药品费用*100
...

Sheet 头颈乳腺外科
A1: 数据名 | B1: 计量单位 | C1: 填报部门 | D1: Y2021 | E1: Y2020 | F1: Y2019 | G1: 指标说明 | H1: 计算公式
A2: 出院患者手术占比 | B2: % | C2: 统计室 | D2: 44.786815 | E2: 35.476443 | F2: 29.81376 | G2: 详见三级公立、二级公立国考手册。举例：30%请填写30（不带百分号），而非写成30%，或0.3。下同 | H2: 出院患者手术台次数/同期出院患者总人次数*100
A3: 出院患者微创手术占比 | B3: % | C3: 统计室 | D3: 7.8 | E3: 0.84872691 | F3: 1.9617966 | G3: 详见三级公立、二级公立国考手册 | H3: 出院患者微创手术台次数/同期出院患者手术台次数*100
A4: 出院患者四级手术比例 | B4: % | C4: 统计室 | D4: 28.4 | E4: 14.827758 | F4: 14.868353 | G4: 详见三级公立国考手册 | H4: 出院患者四级手术台次数/同期出院患者手术台次数*100
A5: 出院患者疑难危重病例比例 | B5: % | C5: 统计室 | D5: 81.6 | E5: 85.05 | F5: 87.56 | G5: 即CD型病例占比 | H5: (疑难病例数+危重病例数)/出院人数*100
A6: 手术患者并发症发生率 | B6: % | C6: 质控科 | D6: 0 | E6: 0 | F6: 0 | G6: 详见国考手册 | H6: 手术患者并发症发生例数/同期出院的手术患者人数*100
A7: I类切口手术部位感染率 | B7: % | C7: 质控科 | D7: 0 | E7: 0.15 | F7: 0.24 | G7: 详见三级中医、三级公立国考手册 | H7: I类切口手术部位感染人次数/同期I类切口手术台次数*100
A8: 大型医用设备检查阳性率 | B8: % | C8: 医务科 | G8: 详见三级中医、三级公立国考手册 | H8: 大型医用设备检查阳性数/同期大型医用设备检查人次数*100
A9: 低风险组病例死亡率 | B9: % | C9: 质控科 | D9: 0 | E9: 0 | F9: 0 | G9: 详见三级公立、二级公立国考手册 | H9: 低风险组死亡例数/低风险组病例数*100
A10: 医院感染发生率 | B10: % | C10: 院感科 | D10: 0.02 | E10: 0.14 | F10: 0.12 | G10: 等级评审标准细则
A11: 抗菌药物使用强度DDDs | B11: DDD | C11: 药学部 | D11: 1.6007262 | E11: 2.8148538 | F11: 3.1358822 | G11: 详见国考手册 | H11: 住院患者抗菌药物消耗量（累计DDD数）/同期收治患者人天数*100
A12: 门诊患者基本药物处方占比 | B12: % | C12: 药学部 | D12: 65.66 | E12: 57.12 | F12: 54.68 | G12: 详见三级中医、三级公立国考手册 | H12: 门诊使用基本药物人次数/同期门诊诊疗总人次数*100
A13: 住院患者基本药物使用率 | B13: % | C13: 药学部 | D13: 98.83 | E13: 94.85 | F13: 83.4 | G13: 详见三级中医、三级公立国考手册 | H13: 出院患者使用基本药物总人次数/同期出院总人次数*100
A14: 重点监控高值医用耗材收入占比 | B14: % | C14: 设备科 | D14: =(302540+48840)/56061415*100 -> 0.6267769 | E14: =236467/49617724*100 -> 0.47657768 | F14: =23400/52577102*100 -> 0.044506067 | G14: 详见国考手册 | H14: 重点监控高值医用耗材收入/同期卫生材料收入*100
A15: 平均住院日 | B15: 天 | C15: 统计室 | D15: 4.67 | E15: 5.46 | F15: 4.96 | G15: 详见二级公立国考手册 | H15: 出院患者占用总床日数/同期出院患者人数
A16: CMI值 | C16: 质控科 | D16: 0.99 | E16: 0.92 | F16: 0.92 | G16: 病例组合指数
A17: DRGs组数 | B17: 组 | C17: 质控科 | D17: 78 | E17: 71 | F17: 91 | G17: 诊断相关分组组数
A18: 核定床位数 | B18: 张 | C18: 统计室 | D18: 85 | E18: 85 | F18: 85 | G18: 等级评审标准细则
A19: 实际开放床位数 | B19: 张 | C19: 统计室 | D19: 82 | E19: 85 | F19: 80 | G19: 等级评审标准细则
A20: 开放床位使用率 | B20: % | C20: 统计室 | D20: 86.33 | E20: 102.94 | F20: 112.15 | G20: 等级评审标准细则 | H20: 实际占用的总床日数/同期实际开放的总床日数*100
A21: 医师人数与开放床位数比 | C21: 人事科 | D21: =D43/D19 -> 0.15853659 | E21: =E43/E19 -> 0.14117647 | F21: =F43/F19 -> 0.15 | G21: 等级评审标准细则，原计量单位为比值（1:X），现改为小数 | H21: 医院执业（助理）医师总数/同期全院实际开放床位数
A22: 护士人数与开放床位数比 | C22: 人事科 | D22: =D44/D19 -> 0.31707317 | E22: =E44/E19 -> 0.47058824 | F22: =F44/F19 -> 0.4875 | G22: 等级评审标准细则，原计量单位为比值（1:X），现改为小数 | H22: 医院注册护士总数/同期全院实际开放床位数
A23: 人均医疗服务收入 | B23: 万元 | C23: 财务科 | D23: 31.202979 | E23: 22.232908 | F23: 22.354122 | G23: 按科室人员数人均医疗服务收入
A24: 人均有效收入 | B24: 万元 | C24: 财务科 | D24: 81.856735 | E24: 58.974829 | F24: 55.852576 | G24: 按科室人员数人均有效收入
A25: 床均医疗服务收入 | B25: 万元 | C25: 财务科 | D25: 17.295301 | E25: 14.895967 | F25: 15.647885 | G25: 按开放床位数床均医疗服务收入
A26: 床均有效收入 | B26: 万元 | C26: 财务科 | D26: 45.37185 | E26: 39.51292 | F26: 39.096803 | G26: 按开放床位数床均有效收入
A27: 每名执业医师日均住院工作负担 | B27: 床日 | C27: 财务科 | D27: 5.5106428 | E27: 7.0611872 | F27: 7.4767123 | G27: 详见三级中医、三级公立国考手册 | H27: 全年实际占用总床日数/医院平均执业(助理)医师人数/365
A28: 医疗服务收入占医疗收入比例 | B28: % | C28: 财务科 | D28: 23.679199 | E28: 23.177579 | F28: 22.855243 | G28: 参考国考手册，原指标名为：医疗服务收入（不含药品、耗材、检查检验收入）占医疗收入比例 | H28: 医疗服务收入/医疗收入*100
A29: 医疗收入 | B29: 万元 | C29: 财务科 | D29: 6061.5946 | E29: 5275.8311 | F29: 5477.2151 | H29: 门诊收入+住院收入
A30: 医疗服务收入 | B30: 万元 | C30: 财务科 | D30: 1435.337 | E30: 1222.8099 | F30: 1251.8308
A31: 有效收入 | B31: 万元 | C31: 财务科 | D31: 3765.4098 | E31: 3243.6156 | F31: 3127.7443 | H31: 医疗服务收入+检查检验收入
A32: 医疗直接成本 | B32: 万元 | D32: 3553.46 | E32: 3258.84 | F32: 3606.82
A33: 收支结余率 | B33: % | D33: 6.14 | E33: 9.3 | F33: 19.77
A34: 万元收入能耗占比 | B34: 吨标煤/万元 | C34: 后勤管理科 | G34: 详见国考手册 | H34: 年总能耗/年总收入*10000
A35: 门诊收入占医疗收入比例 | B35: % | C35: 财务科 | D35: 18.457595 | E35: 16.486996 | F35: 14.246373 | G35: 详见三级公立国考手册 | H35: 门诊收入/医疗收入*100
A36: 住院收入占医疗收入比例 | B36: % | C36: 财务科 | D36: 81.542405 | E36: 83.513004 | F36: 85.753627 | G36: 详见三级公立国考手册 | H36: 住院收入/医疗收入*100
A37: 医疗收入增幅 | B37: % | C37: 财务科 | D37: 14.893644 | E37: -3.6767598 | F37: 24.008013 | G37: 详见国考手册 | H37: （本年度医疗收入－上一年度医疗收入）/上一年度医疗收入*100
A38: 门诊次均费用增幅 | B38: % | C38: 财务科 | D38: 6.5654787 | E38: 18.436958 | F38: 13.419844 | G38: 详见国考手册 | H38: （本年度门诊患者次均医药费用－上一年度门诊患者次均医药费用）/上一年度门诊患者次均医药费用*100
A39: 住院次均费用增幅 | B39: % | C39: 财务科 | D39: 13.495085 | E39: 9.3358433 | F39: 2.359181 | G39: 详见国考手册 | H39: （本年度出院患者次均医药费用－上一年度出院患者次均医药费用）/上一年度出院患者次均医药费用*100
A40: 门诊次均药品费用增幅 | B40: % | C40: 财务科 | D40: 6.369115 | E40: 90.876535 | F40: 14.024844 | G40: 详见国考手册 | H40: （本年度门诊患者次均药品费用－上一年度门诊患者次均药品费用）/上一年度门诊患者次均药品费用*100
...

Sheet 胃肠外科
A1: 数据名 | B1: 计量单位 | C1: 填报部门 | D1: Y2021 | E1: Y2020 | F1: Y2019 | G1: 指标说明 | H1: 计算公式
A2: 出院患者手术占比 | B2: % | C2: 统计室 | D2: 37.416728 | E2: 32.102672 | F2: 32.84949 | G2: 详见三级公立、二级公立国考手册。举例：30%请填写30（不带百分号），而非写成30%，或0.3。下同 | H2: 出院患者手术台次数/同期出院患者总人次数*100
A3: 出院患者微创手术占比 | B3: % | C3: 统计室 | D3: 53.363007 | E3: 54.874042 | F3: 43.92425 | G3: 详见三级公立、二级公立国考手册 | H3: 出院患者微创手术台次数/同期出院患者手术台次数*100
A4: 出院患者四级手术比例 | B4: % | C4: 统计室 | D4: 32.492582 | E4: 34.720701 | F4: 32.456602 | G4: 详见三级公立国考手册 | H4: 出院患者四级手术台次数/同期出院患者手术台次数*100
A5: 出院患者疑难危重病例比例 | B5: % | C5: 统计室 | D5: 95.97 | E5: 95.43 | F5: 92.41 | G5: 即CD型病例占比 | H5: (疑难病例数+危重病例数)/出院人数*100
A6: 手术患者并发症发生率 | B6: % | C6: 质控科 | D6: 0 | E6: 0 | F6: 0 | G6: 详见国考手册 | H6: 手术患者并发症发生例数/同期出院的手术患者人数*100
A7: I类切口手术部位感染率 | B7: % | C7: 质控科 | D7: 0 | E7: 0.2 | F7: 0.52 | G7: 详见三级中医、三级公立国考手册 | H7: I类切口手术部位感染人次数/同期I类切口手术台次数*100
A8: 大型医用设备检查阳性率 | B8: % | C8: 医务科 | G8: 详见三级中医、三级公立国考手册 | H8: 大型医用设备检查阳性数/同期大型医用设备检查人次数*100
A9: 低风险组病例死亡率 | B9: % | C9: 质控科 | D9: 0 | E9: 0 | F9: 0 | G9: 详见三级公立、二级公立国考手册 | H9: 低风险组死亡例数/低风险组病例数*100
A10: 医院感染发生率 | B10: % | C10: 院感科 | D10: 1.09 | E10: 1.16 | F10: 1.66 | G10: 等级评审标准细则
A11: 抗菌药物使用强度DDDs | B11: DDD | C11: 药学部 | D11: 46.052634 | E11: 46.386234 | F11: 40.892234 | G11: 详见国考手册 | H11: 住院患者抗菌药物消耗量（累计DDD数）/同期收治患者人天数*100
A12: 门诊患者基本药物处方占比 | B12: % | C12: 药学部 | D12: 71.5 | E12: 51.61 | F12: 44.6 | G12: 详见三级中医、三级公立国考手册 | H12: 门诊使用基本药物人次数/同期门诊诊疗总人次数*100
A13: 住院患者基本药物使用率 | B13: % | C13: 药学部 | D13: 97.5 | E13: 97.88 | F13: 95.3 | G13: 详见三级中医、三级公立国考手册 | H13: 出院患者使用基本药物总人次数/同期出院总人次数*100
A14: 重点监控高值医用耗材收入占比 | B14: % | C14: 设备科 | D14: =(55900+48840)/60839917*100 -> 0.17215671 | E14: =57900/60915806*100 -> 0.095049223 | F14: 0 | G14: 详见国考手册 | H14: 重点监控高值医用耗材收入/同期卫生材料收入*100
A15: 平均住院日 | B15: 天 | C15: 统计室 | D15: 7.09 | E15: 6.93 | F15: 7.1 | G15: 详见二级公立国考手册 | H15: 出院患者占用总床日数/同期出院患者人数
A16: CMI值 | C16: 质控科 | D16: 1.52 | E16: 1.43 | F16: 1.41 | G16: 病例组合指数
A17: DRGs组数 | B17: 组 | C17: 质控科 | D17: 160 | E17: 153 | F17: 171 | G17: 诊断相关分组组数
A18: 核定床位数 | B18: 张 | C18: 统计室 | D18: 90 | E18: 90 | F18: 90 | G18: 等级评审标准细则
A19: 实际开放床位数 | B19: 张 | C19: 统计室 | D19: 100 | E19: 100 | F19: 100 | G19: 等级评审标准细则
A20: 开放床位使用率 | B20: % | C20: 统计室 | D20: 101.77 | E20: 104.54 | F20: 109.28 | G20: 等级评审标准细则 | H20: 实际占用的总床日数/同期实际开放的总床日数*100
A21: 医师人数与开放床位数比 | C21: 人事科 | D21: =D43/D19 -> 0.18 | E21: =E43/E19 -> 0.18 | F21: =F43/F19 -> 0.18 | G21: 等级评审标准细则，原计量单位为比值（1:X），现改为小数 | H21: 医院执业（助理）医师总数/同期全院实际开放床位数
A22: 护士人数与开放床位数比 | C22: 人事科 | D22: =D44/D19 -> 0.46 | E22: =E44/E19 -> 0.45 | F22: =F44/F19 -> 0.46 | G22: 等级评审标准细则，原计量单位为比值（1:X），现改为小数 | H22: 医院注册护士总数/同期全院实际开放床位数
A23: 人均医疗服务收入 | B23: 万元 | C23: 财务科 | D23: 29.612724 | E23: 27.934196 | F23: 28.56485 | G23: 按科室人员数人均医疗服务收入
A24: 人均有效收入 | B24: 万元 | C24: 财务科 | D24: 59.67313 | E24: 56.512557 | F24: 58.007161 | G24: 按科室人员数人均有效收入
A25: 床均医疗服务收入 | B25: 万元 | C25: 财务科 | D25: 19.544398 | E25: 18.995253 | F25: 18.567153 | G25: 按开放床位数床均医疗服务收入
A26: 床均有效收入 | B26: 万元 | C26: 财务科 | D26: 39.384266 | E26: 38.428539 | F26: 37.704655 | G26: 按开放床位数床均有效收入
A27: 每名执业医师日均住院工作负担 | B27: 床日 | C27: 财务科 | D27: 5.6537291 | E27: 5.8237443 | F27: 6.0712329 | G27: 详见三级中医、三级公立国考手册 | H27: 全年实际占用总床日数/医院平均执业(助理)医师人数/365
A28: 医疗服务收入占医疗收入比例 | B28: % | C28: 财务科 | D28: 28.968177 | E28: 28.645276 | F28: 27.331443 | G28: 参考国考手册，原指标名为：医疗服务收入（不含药品、耗材、检查检验收入）占医疗收入比例 | H28: 医疗服务收入/医疗收入*100
A29: 医疗收入 | B29: 万元 | C29: 财务科 | D29: 6746.8512 | E29: 6631.1991 | F29: 6793.3304 | H29: 门诊收入+住院收入
A30: 医疗服务收入 | B30: 万元 | C30: 财务科 | D30: 1954.4398 | E30: 1899.5253 | F30: 1856.7153
A31: 有效收入 | B31: 万元 | C31: 财务科 | D31: 3938.4266 | E31: 3842.8539 | F31: 3770.4655 | H31: 医疗服务收入+检查检验收入
A32: 医疗直接成本 | B32: 万元 | D32: 4112.92 | E32: 3699.12 | F32: 3814.5
A33: 收支结余率 | B33: % | D33: 16.78 | E33: 15.75 | F33: 11.37
A34: 万元收入能耗占比 | B34: 吨标煤/万元 | C34: 后勤管理科 | G34: 详见国考手册 | H34: 年总能耗/年总收入*10000
A35: 门诊收入占医疗收入比例 | B35: % | C35: 财务科 | D35: 6.738559 | E35: 5.9830235 | F35: 5.6201895 | G35: 详见三级公立国考手册 | H35: 门诊收入/医疗收入*100
A36: 住院收入占医疗收入比例 | B36: % | C36: 财务科 | D36: 93.261441 | E36: 94.016977 | F36: 94.37981 | G36: 详见三级公立国考手册 | H36: 住院收入/医疗收入*100
A37: 医疗收入增幅 | B37: % | C37: 财务科 | D37: 1.7440608 | E37: -2.3866251 | F37: 16.957931 | G37: 详见国考手册 | H37: （本年度医疗收入－上一年度医疗收入）/上一年度医疗收入*100
A38: 门诊次均费用增幅 | B38: % | C38: 财务科 | D38: 10.661835 | E38: 14.5602 | F38: 14.593392 | G38: 详见国考手册 | H38: （本年度门诊患者次均医药费用－上一年度门诊患者次均医药费用）/上一年度门诊患者次均医药费用*100
A39: 住院次均费用增幅 | B39: % | C39: 财务科 | D39: 6.3616861 | E39: -1.0543114 | F39: 8.732032 | G39: 详见国考手册 | H39: （本年度出院患者次均医药费用－上一年度出院患者次均医药费用）/上一年度出院患者次均医药费用*100
A40: 门诊次均药品费用增幅 | B40: % | C40: 财务科 | D40: 36.022247 | E40: 50.335019 | F40: 29.044004 | G40: 详见国考手册 | H40: （本年度门诊患者次均药品费用－上一年度门诊患者次均药品费用）/上一年度门诊患者次均药品费用*100
...

Sheet 胸外科
A1: 数据名 | B1: 计量单位 | C1: 填报部门 | D1: Y2021 | E1: Y2020 | F1: Y2019 | G1: 指标说明 | H1: 计算公式
A2: 出院患者手术占比 | B2: % | C2: 统计室 | D2: 30 | E2: 20.97561 | F2: 19.842989 | G2: 详见三级公立、二级公立国考手册。举例：30%请填写30（不带百分号），而非写成30%，或0.3。下同 | H2: 出院患者手术台次数/同期出院患者总人次数*100
A3: 出院患者微创手术占比 | B3: % | C3: 统计室 | D3: 85.163776 | E3: 79.198966 | F3: 82.946794 | G3: 详见三级公立、二级公立国考手册 | H3: 出院患者微创手术台次数/同期出院患者手术台次数*100
A4: 出院患者四级手术比例 | B4: % | C4: 统计室 | D4: 85.934489 | E4: 79.97416 | F4: 82.673943 | G4: 详见三级公立国考手册 | H4: 出院患者四级手术台次数/同期出院患者手术台次数*100
A5: 出院患者疑难危重病例比例 | B5: % | C5: 统计室 | D5: 97.11 | E5: 95.58 | F5: 96.7 | G5: 即CD型病例占比 | H5: (疑难病例数+危重病例数)/出院人数*100
A6: 手术患者并发症发生率 | B6: % | C6: 质控科 | D6: 0 | E6: 0 | F6: 0 | G6: 详见国考手册 | H6: 手术患者并发症发生例数/同期出院的手术患者人数*100
A7: I类切口手术部位感染率 | B7: % | C7: 质控科 | D7: 0 | E7: 0 | F7: 0 | G7: 详见三级中医、三级公立国考手册 | H7: I类切口手术部位感染人次数/同期I类切口手术台次数*100
A8: 大型医用设备检查阳性率 | B8: % | C8: 医务科 | G8: 详见三级中医、三级公立国考手册 | H8: 大型医用设备检查阳性数/同期大型医用设备检查人次数*100
A9: 低风险组病例死亡率 | B9: % | C9: 质控科 | D9: 0 | E9: 0 | F9: 0 | G9: 详见三级公立、二级公立国考手册 | H9: 低风险组死亡例数/低风险组病例数*100
A10: 医院感染发生率 | B10: % | C10: 院感科 | D10: 0.38 | E10: 0.51 | F10: 0.78 | G10: 等级评审标准细则
A11: 抗菌药物使用强度DDDs | B11: DDD | C11: 药学部 | D11: 49.760806 | E11: 35.052652 | F11: 33.901218 | G11: 详见国考手册 | H11: 住院患者抗菌药物消耗量（累计DDD数）/同期收治患者人天数*100
A12: 门诊患者基本药物处方占比 | B12: % | C12: 药学部 | D12: 60.58 | E12: 80 | F12: 40.35 | G12: 详见三级中医、三级公立国考手册 | H12: 门诊使用基本药物人次数/同期门诊诊疗总人次数*100
A13: 住院患者基本药物使用率 | B13: % | C13: 药学部 | D13: 92.17 | E13: 93.09 | F13: 87.08 | G13: 详见三级中医、三级公立国考手册 | H13: 出院患者使用基本药物总人次数/同期出院总人次数*100
A14: 重点监控高值医用耗材收入占比 | B14: % | C14: 设备科 | D14: =1/56351599*100 -> 1.7745725e-06 | E14: =1075200/55860751*100 -> 1.9247862 | F14: =1/54607463*100 -> 1.8312515e-06 | G14: 详见国考手册 | H14: 重点监控高值医用耗材收入/同期卫生材料收入*100
A15: 平均住院日 | B15: 天 | C15: 统计室 | D15: 7.44 | E15: 7.9 | F15: 8.3 | G15: 详见二级公立国考手册 | H15: 出院患者占用总床日数/同期出院患者人数
A16: CMI值 | C16: 质控科 | D16: 1.95 | E16: 1.63 | F16: 1.76 | G16: 病例组合指数
A17: DRGs组数 | B17: 组 | C17: 质控科 | D17: 129 | E17: 138 | F17: 140 | G17: 诊断相关分组组数
A18: 核定床位数 | B18: 张 | C18: 统计室 | D18: 75 | E18: 75 | F18: 75 | G18: 等级评审标准细则
A19: 实际开放床位数 | B19: 张 | C19: 统计室 | D19: 77 | E19: 75 | F19: 71 | G19: 等级评审标准细则
A20: 开放床位使用率 | B20: % | C20: 统计室 | D20: 87.38 | E20: 105.75 | F20: 117.48 | G20: 等级评审标准细则 | H20: 实际占用的总床日数/同期实际开放的总床日数*100
A21: 医师人数与开放床位数比 | C21: 人事科 | D21: =D43/D19 -> 0.12987013 | E21: =E43/E19 -> 0.14666667 | F21: =F43/F19 -> 0.15492958 | G21: 等级评审标准细则，原计量单位为比值（1:X），现改为小数 | H21: 医院执业（助理）医师总数/同期全院实际开放床位数
A22: 护士人数与开放床位数比 | C22: 人事科 | D22: =D44/D19 -> 0.31168831 | E22: =E44/E19 -> 0.36 | F22: =F44/F19 -> 0.43661972 | G22: 等级评审标准细则，原计量单位为比值（1:X），现改为小数 | H22: 医院注册护士总数/同期全院实际开放床位数
A23: 人均医疗服务收入 | B23: 万元 | C23: 财务科 | D23: 35.239787 | E23: 32.232985 | F23: 34.08213 | G23: 按科室人员数人均医疗服务收入
A24: 人均有效收入 | B24: 万元 | C24: 财务科 | D24: 70.502028 | E24: 71.701404 | F24: 66.248631 | G24: 按科室人员数人均有效收入
A25: 床均医疗服务收入 | B25: 万元 | C25: 财务科 | D25: 18.926267 | E25: 17.298561 | F25: 18.72117 | G25: 按开放床位数床均医疗服务收入
A26: 床均有效收入 | B26: 万元 | C26: 财务科 | D26: 37.864595 | E26: 38.480181 | F26: 36.390093 | G26: 按开放床位数床均有效收入
A27: 每名执业医师日均住院工作负担 | B27: 床日 | C27: 财务科 | D27: 6.6709589 | E27: 7.0057285 | F27: 7.5825654 | G27: 详见三级中医、三级公立国考手册 | H27: 全年实际占用总床日数/医院平均执业(助理)医师人数/365
A28: 医疗服务收入占医疗收入比例 | B28: % | C28: 财务科 | D28: 23.199972 | E28: 20.732901 | F28: 22.880764 | G28: 参考国考手册，原指标名为：医疗服务收入（不含药品、耗材、检查检验收入）占医疗收入比例 | H28: 医疗服务收入/医疗收入*100
A29: 医疗收入 | B29: 万元 | C29: 财务科 | D29: 6227.7284 | E29: 6063.2442 | F29: 5809.2601 | H29: 门诊收入+住院收入
A30: 医疗服务收入 | B30: 万元 | C30: 财务科 | D30: 1444.8313 | E30: 1257.0864 | F30: 1329.2031
A31: 有效收入 | B31: 万元 | C31: 财务科 | D31: 2890.5831 | E31: 2796.3548 | F31: 2583.6966 | H31: 医疗服务收入+检查检验收入
A32: 医疗直接成本 | B32: 万元 | D32: 3439.25 | E32: 3405.06 | F32: 3345.08
A33: 收支结余率 | B33: % | D33: 19.94 | E33: 22.62 | F33: 25.46
A34: 万元收入能耗占比 | B34: 吨标煤/万元 | C34: 后勤管理科 | G34: 详见国考手册 | H34: 年总能耗/年总收入*10000
A35: 门诊收入占医疗收入比例 | B35: % | C35: 财务科 | D35: 15.369214 | E35: 11.013109 | F35: 2.8855431 | G35: 详见三级公立国考手册 | H35: 门诊收入/医疗收入*100
A36: 住院收入占医疗收入比例 | B36: % | C36: 财务科 | D36: 84.630786 | E36: 88.986891 | F36: 97.114457 | G36: 详见三级公立国考手册 | H36: 住院收入/医疗收入*100
A37: 医疗收入增幅 | B37: % | C37: 财务科 | D37: 2.7128083 | E37: 4.372057 | F37: 26.337406 | G37: 详见国考手册 | H37: （本年度医疗收入－上一年度医疗收入）/上一年度医疗收入*100
A38: 门诊次均费用增幅 | B38: % | C38: 财务科 | D38: 12.1991 | E38: 247.66235 | F38: 2.7969211 | G38: 详见国考手册 | H38: （本年度门诊患者次均医药费用－上一年度门诊患者次均医药费用）/上一年度门诊患者次均医药费用*100
A39: 住院次均费用增幅 | B39: % | C39: 财务科 | D39: 6.274852 | E39: -1.4768585 | F39: 11.995076 | G39: 详见国考手册 | H39: （本年度出院患者次均医药费用－上一年度出院患者次均医药费用）/上一年度出院患者次均医药费用*100
A40: 门诊次均药品费用增幅 | B40: % | C40: 财务科 | D40: 15.16227 | E40: 1653.4715 | F40: -5.6922404 | G40: 详见国考手册 | H40: （本年度门诊患者次均药品费用－上一年度门诊患者次均药品费用）/上一年度门诊患者次均药品费用*100
...

Sheet 神经外科
A1: 数据名 | B1: 计量单位 | C1: 填报部门 | D1: Y2021 | E1: Y2020 | F1: Y2019 | G1: 指标说明 | H1: 计算公式
A2: 出院患者手术占比 | B2: % | C2: 统计室 | D2: 29.261273 | E2: 31.041322 | F2: 32.273919 | G2: 详见三级公立、二级公立国考手册。举例：30%请填写30（不带百分号），而非写成30%，或0.3。下同 | H2: 出院患者手术台次数/同期出院患者总人次数*100
A3: 出院患者微创手术占比 | B3: % | C3: 统计室 | D3: 11.147541 | E3: 3.9403621 | F3: 2.8426396 | G3: 详见三级公立、二级公立国考手册 | H3: 出院患者微创手术台次数/同期出院患者手术台次数*100
A4: 出院患者四级手术比例 | B4: % | C4: 统计室 | D4: 41.639344 | E4: 41.746539 | F4: 41.218274 | G4: 详见三级公立国考手册 | H4: 出院患者四级手术台次数/同期出院患者手术台次数*100
A5: 出院患者疑难危重病例比例 | B5: % | C5: 统计室 | D5: 92.375 | E5: 92.535 | F5: 92.1675 | G5: 即CD型病例占比 | H5: (疑难病例数+危重病例数)/出院人数*100
A6: 手术患者并发症发生率 | B6: % | C6: 质控科 | D6: 0 | E6: 0 | F6: 0 | G6: 详见国考手册 | H6: 手术患者并发症发生例数/同期出院的手术患者人数*100
A7: I类切口手术部位感染率 | B7: % | C7: 质控科 | D7: 0.06 | E7: 0.05 | F7: 0 | G7: 详见三级中医、三级公立国考手册 | H7: I类切口手术部位感染人次数/同期I类切口手术台次数*100
A8: 大型医用设备检查阳性率 | B8: % | C8: 医务科 | G8: 详见三级中医、三级公立国考手册 | H8: 大型医用设备检查阳性数/同期大型医用设备检查人次数*100
A9: 低风险组病例死亡率 | B9: % | C9: 质控科 | D9: 0 | E9: 0 | F9: 0 | G9: 详见三级公立、二级公立国考手册 | H9: 低风险组死亡例数/低风险组病例数*100
A10: 医院感染发生率 | B10: % | C10: 院感科 | D10: 3.76 | E10: 4.39 | F10: 5.24 | G10: 等级评审标准细则
A11: 抗菌药物使用强度DDDs | B11: DDD | C11: 药学部 | D11: 50.06 | E11: 54.42 | F11: 196.02 | G11: 详见国考手册 | H11: 住院患者抗菌药物消耗量（累计DDD数）/同期收治患者人天数*100
A12: 门诊患者基本药物处方占比 | B12: % | C12: 药学部 | D12: 82.38 | E12: 67.66 | F12: 61.56 | G12: 详见三级中医、三级公立国考手册 | H12: 门诊使用基本药物人次数/同期门诊诊疗总人次数*100
A13: 住院患者基本药物使用率 | B13: % | C13: 药学部 | D13: 97.92 | E13: 98.08 | F13: 94.31 | G13: 详见三级中医、三级公立国考手册 | H13: 出院患者使用基本药物总人次数/同期出院总人次数*100
A14: 重点监控高值医用耗材收入占比 | B14: % | C14: 设备科 | D14: =(2502461+416598)/41054915*100 -> 7.1101329 | E14: =3662543/39973299*100 -> 9.1624737 | F14: =1716817.5/59549948*100 -> 2.8829874 | G14: 详见国考手册 | H14: 重点监控高值医用耗材收入/同期卫生材料收入*100
A15: 平均住院日 | B15: 天 | C15: 统计室 | D15: 15.64 | E15: 16.535 | F15: 13.5125 | G15: 详见二级公立国考手册 | H15: 出院患者占用总床日数/同期出院患者人数
A16: CMI值 | C16: 质控科 | D16: 2.865 | E16: 3 | F16: 2.705 | G16: 病例组合指数
A17: DRGs组数 | B17: 组 | C17: 质控科 | D17: 124 | E17: 131 | F17: 90 | G17: 诊断相关分组组数
A18: 核定床位数 | B18: 张 | C18: 统计室 | D18: 130 | E18: 130 | F18: 130 | G18: 等级评审标准细则
A19: 实际开放床位数 | B19: 张 | C19: 统计室 | D19: 140 | E19: 130 | F19: 120 | G19: 等级评审标准细则
A20: 开放床位使用率 | B20: % | C20: 统计室 | D20: 104.045 | E20: 118.75 | F20: 102.6025 | G20: 等级评审标准细则 | H20: 实际占用的总床日数/同期实际开放的总床日数*100
